Workbook

Sheet Theatre
N1: VENUE TOTAL | Q1: PARTNER SPLIT
B2: ***MAJESTIC THEATRE RESULTS*** | N2: MAJESTIC THEATRE | Q2: MTC, Inc. | T2: AEG
B3: Name | C3: Date | D3: Day of the week | E3: Tickets Sold | F3: Venue Capacity | G3: Capacity Rate | H3: Gross Ticket Revenue | I3: Avg. Ticket Price (including TW rebate) | J3: Bar Revenue | K3: Avg sale of alcohol per guest | L3: Band(s) guarantee | M3: % of Gross Ticket Revenue | N3: Gate Settlement Gain/(Loss) | O3: Bar Sales - 100% | P3: Show Gross Proceeds (before COGS, Labor, & Facility Costs) | Q3: Gate Settlement Gain/(Loss) | R3: Bar Sales - 70% | S3: Show Gross Proceeds (before COGS, Labor, & Facility Costs) | T3: Gate Settlement Gain/(Loss) | U3: Bar Sales - 30% | V3: Show Gross Proceeds | W3: INPUT - Total Gate Settlement
B4: TOTALS | E4: =SUM(E7:E108) -> 48058 | F4: =SUM(F7:F108) -> 79903 | H4: =SUM(H7:H108) -> 1567678.5 | J4: =SUM(J7:J108) -> 469010.18 | L4: =SUM(L7:L108) -> 916655.94 | M4: =SUM(M7:M108) -> 53.699747 | N4: =SUM(N7:N108) -> 89341.569 | O4: =SUM(O7:O108) -> 469010.18 | P4: =SUM(P7:P108) -> 558351.75 | Q4: =SUM(Q7:Q108) -> 44670.785 | R4: =SUM(R7:R108) -> 328307.13 | S4: =SUM(S7:S108) -> 372977.91 | ... V4: =SUM(V7:V108) -> 185373.84
B5: AVERAGES | E5: =E4/COUNTA(E7:E108) -> 608.32911 | F5: =F4/COUNTA(F7:F108) -> 1011.4304 | G5: =E4/F4 -> 0.60145426 | H5: =H4/COUNTA(H7:H108) -> 19844.031 | I5: =H4/E4 -> 32.620551 | J5: =J4/COUNTA(J7:J108) -> 5650.7251 | K5: =J4/E4 -> 9.759253 | L5: =L4/COUNTA(L7:L108) -> 11603.24 | M5: =L4/H4 -> 0.58472191 | N5: =N4/COUNTA(N7:N108) -> 1076.4044 | O5: =O4/COUNTA(O7:O108) -> 5650.7251 | P5: =P4/COUNTA(P7:P108) -> 6727.1295 | Q5: =Q4/COUNTA(Q7:Q108) -> 551.49117 | R5: =R4/COUNTA(R7:R108) -> 3955.5075 | S5: =S4/COUNTA(S7:S108) -> 4493.7098 | T5: =T4/COUNTA(T7:T108) -> 551.49117 | U5: =U4/COUNTA(U7:U108) -> 1695.2175 | V5: =V4/COUNTA(V7:V108) -> 2233.4197
A7: 1 | B7: Noname | C7: 43467 | D7: =C7 -> 43467 | E7: 1092 | F7: 1100 | G7: =IFERROR(E7/F7,"") -> 0.99272727 | H7: 34484 | I7: =IFERROR(H7/E7,"") -> 31.578755 | J7: 4600.91 | K7: =IFERROR(J7/E7,"") -> 4.2132875 | L7: 16500 | M7: =L7/H7 -> 0.47848277 | N7: =Q7+T7 -> 11365.64 | O7: =R7+U7 -> 4600.91 | P7: =N7+O7 -> 15966.55 | Q7: =W7*50% -> 5682.82 | R7: =J7*70% -> 3220.637 | S7: =Q7+R7 -> 8903.457 | T7: =Q7 -> 5682.82 | U7: =J7*30% -> 1380.273 | V7: =T7+U7 -> 7063.093 | W7: 11365.64
A8: 2 | B8: Ookay (1) | C8: 43470 | D8: =C8 -> 43470 | E8: 658 | F8: 1100 | G8: =IFERROR(E8/F8,"") -> 0.59818182 | H8: 15822.5 | I8: =IFERROR(H8/E8,"") -> 24.046353 | J8: 9016.06 | K8: =IFERROR(J8/E8,"") -> 13.702219 | L8: 7500 | M8: =L8/H8 -> 0.47400853 | N8: =Q8+T8 -> 1217.2121 | O8: =R8+U8 -> 9016.06 | P8: =N8+O8 -> 10233.272 | Q8: =W8*33.3333% -> 608.60606 | R8: =J8*70% -> 6311.242 | S8: =Q8+R8 -> 6919.8481 | T8: =Q8 -> 608.60606 | U8: =J8*30% -> 2704.818 | V8: =T8+U8 -> 3313.4241 | W8: 1825.82
A9: 3 | B9: Piff the Magic Dragon | C9: 43489 | D9: =C9 -> 43489 | E9: 325 | F9: 400 | G9: =IFERROR(E9/F9,"") -> 0.8125 | H9: 16471 | I9: =IFERROR(H9/E9,"") -> 50.68 | J9: 1563.51 | K9: =IFERROR(J9/E9,"") -> 4.8108 | L9: 6000 | M9: =L9/H9 -> 0.36427661 | N9: =Q9+T9 -> 2128.28 | O9: =R9+U9 -> 1563.51 | P9: =N9+O9 -> 3691.79 | Q9: =W9*50% -> 1064.14 | R9: =J9*70% -> 1094.457 | S9: =Q9+R9 -> 2158.597 | T9: =Q9 -> 1064.14 | U9: =J9*30% -> 469.053 | V9: =T9+U9 -> 1533.193 | W9: 2128.28
A10: 4 | B10: The Amity Affliction | C10: 43491 | D10: =C10 -> 43491 | E10: 1100 | F10: 1100 | G10: =IFERROR(E10/F10,"") -> 1 | H10: 37758 | I10: =IFERROR(H10/E10,"") -> 34.325455 | J10: 12222.24 | K10: =IFERROR(J10/E10,"") -> 11.111127 | L10: 15516.32 | M10: =L10/H10 -> 0.41094126 | N10: =Q10+T10 -> 11019.12 | O10: =R10+U10 -> 12222.24 | P10: =N10+O10 -> 23241.36 | Q10: =W10*50% -> 5509.56 | R10: =J10*70% -> 8555.568 | S10: =Q10+R10 -> 14065.128 | T10: =Q10 -> 5509.56 | U10: =J10*30% -> 3666.672 | V10: =T10+U10 -> 9176.232 | W10: 11019.12
A11: 5 | B11: Nao | C11: 43492 | D11: =C11 -> 43492 | E11: 961 | F11: 1000 | G11: =IFERROR(E11/F11,"") -> 0.961 | H11: 30066.5 | I11: =IFERROR(H11/E11,"") -> 31.286681 | J11: 6018.26 | K11: =IFERROR(J11/E11,"") -> 6.2624974 | L11: 15763.8 | M11: =L11/H11 -> 0.52429781 | N11: =Q11+T11 -> 7719.22 | O11: =R11+U11 -> 6018.26 | P11: =N11+O11 -> 13737.48 | Q11: =W11*50% -> 3859.61 | R11: =J11*70% -> 4212.782 | S11: =Q11+R11 -> 8072.392 | T11: =Q11 -> 3859.61 | U11: =J11*30% -> 1805.478 | V11: =T11+U11 -> 5665.088 | W11: 7719.22
A12: 6 | B12: Spafford | C12: 43498 | D12: =C12 -> 43498 | E12: 499 | F12: 1100 | G12: =IFERROR(E12/F12,"") -> 0.45363636 | H12: 12212.5 | I12: =IFERROR(H12/E12,"") -> 24.473948 | J12: 9715.38 | K12: =IFERROR(J12/E12,"") -> 19.469699 | L12: 5119 | M12: =L12/H12 -> 0.4191607 | N12: =Q12+T12 -> 738.14 | O12: =R12+U12 -> 9715.38 | P12: =N12+O12 -> 10453.52 | Q12: =W12*50% -> 369.07 | R12: =J12*70% -> 6800.766 | S12: =Q12+R12 -> 7169.836 | T12: =Q12 -> 369.07 | U12: =J12*30% -> 2914.614 | V12: =T12+U12 -> 3283.684 | W12: 738.14
A13: 7 | B13: Sharon Van Etten | C13: 43509 | D13: =C13 -> 43509 | E13: 417 | F13: 1000 | G13: =IFERROR(E13/F13,"") -> 0.417 | H13: 12917.5 | I13: =IFERROR(H13/E13,"") -> 30.977218 | J13: 3653.31 | K13: =IFERROR(J13/E13,"") -> 8.7609353 | L13: 8000 | M13: =L13/H13 -> 0.61931488 | N13: =Q13+T13 -> -449.14 | O13: =R13+U13 -> 3653.31 | P13: =N13+O13 -> 3204.17 | Q13: =W13*50% -> -224.57 | R13: =J13*70% -> 2557.317 | S13: =Q13+R13 -> 2332.747 | T13: =Q13 -> -224.57 | U13: =J13*30% -> 1095.993 | V13: =T13+U13 -> 871.423 | W13: -449.14
A14: 8 | B14: Space Jesus (1) | C14: 43511 | D14: =C14 -> 43511 | E14: 1100 | F14: 1100 | G14: =IFERROR(E14/F14,"") -> 1 | H14: 34369 | I14: =IFERROR(H14/E14,"") -> 31.244545 | J14: 11658.7 | K14: =IFERROR(J14/E14,"") -> 10.598818 | L14: 15500 | M14: =L14/H14 -> 0.45098781 | N14: =Q14+T14 -> 7689.7523 | O14: =R14+U14 -> 11658.7 | P14: =N14+O14 -> 19348.452 | Q14: =W14*33.3333% -> 3844.8762 | R14: =J14*70% -> 8161.09 | S14: =Q14+R14 -> 12005.966 | T14: =Q14 -> 3844.8762 | U14: =J14*30% -> 3497.61 | V14: =T14+U14 -> 7342.4862 | W14: 11534.64
A15: 9 | B15: Kurt Vile | C15: 43515 | D15: =C15 -> 43515 | E15: 814 | F15: 1100 | G15: =IFERROR(E15/F15,"") -> 0.74 | H15: 26731 | I15: =IFERROR(H15/E15,"") -> 32.839066 | J15: 10123.62 | K15: =IFERROR(J15/E15,"") -> 12.43688 | L15: 20750 | M15: =L15/H15 -> 0.77625229 | N15: =Q15+T15 -> -380.12 | O15: =R15+U15 -> 10123.62 | P15: =N15+O15 -> 9743.5 | Q15: =W15*50% -> -190.06 | R15: =J15*70% -> 7086.534 | S15: =Q15+R15 -> 6896.474 | T15: =Q15 -> -190.06 | U15: =J15*30% -> 3037.086 | V15: =T15+U15 -> 2847.026 | W15: -380.12
A16: 10 | B16: Yung Gravy | C16: 43519 | D16: =C16 -> 43519 | E16: 1100 | F16: 1100 | G16: =IFERROR(E16/F16,"") -> 1 | H16: 37283 | I16: =IFERROR(H16/E16,"") -> 33.893636 | J16: 3341.27 | K16: =IFERROR(J16/E16,"") -> 3.0375182 | L16: 13556.69 | M16: =L16/H16 -> 0.36361586 | N16: =Q16+T16 -> 13305.32 | O16: =R16+U16 -> 3341.27 | P16: =N16+O16 -> 16646.59 | Q16: =W16*50% -> 6652.66 | R16: =J16*70% -> 2338.889 | S16: =Q16+R16 -> 8991.549 | T16: =Q16 -> 6652.66 | U16: =J16*30% -> 1002.381 | V16: =T16+U16 -> 7655.041 | W16: 13305.32
A17: 11 | B17: Cold Cave | C17: 43524 | D17: =C17 -> 43524 | E17: 224 | F17: 1000 | G17: =IFERROR(E17/F17,"") -> 0.224 | H17: 5844 | I17: =IFERROR(H17/E17,"") -> 26.089286 | J17: 4204.03 | K17: =IFERROR(J17/E17,"") -> 18.767991 | L17: 4350 | M17: =L17/H17 -> 0.74435318 | N17: =Q17+T17 -> -3860.62 | O17: =R17+U17 -> 4204.03 | P17: =N17+O17 -> 343.41 | Q17: =W17*50% -> -1930.31 | R17: =J17*70% -> 2942.821 | S17: =Q17+R17 -> 1012.511 | T17: =Q17 -> -1930.31 | U17: =J17*30% -> 1261.209 | V17: =T17+U17 -> -669.101 | W17: -3860.62
A18: 12 | B18: Jacob Banks | C18: 43525 | D18: =C18 -> 43525 | E18: 397 | F18: 1000 | G18: =IFERROR(E18/F18,"") -> 0.397 | H18: 12868 | I18: =IFERROR(H18/E18,"") -> 32.413098 | J18: 4903.83 | K18: =IFERROR(J18/E18,"") -> 12.352217 | L18: 7500 | M18: =L18/H18 -> 0.58284116 | N18: =Q18+T18 -> -994.08 | O18: =R18+U18 -> 4903.83 | P18: =N18+O18 -> 3909.75 | Q18: =W18*50% -> -497.04 | R18: =J18*70% -> 3432.681 | S18: =Q18+R18 -> 2935.641 | T18: =Q18 -> -497.04 | U18: =J18*30% -> 1471.149 | V18: =T18+U18 -> 974.109 | W18: -994.08
A19: 13 | B19: Wet | C19: 43532 | D19: =C19 -> 43532 | E19: 177 | F19: 1000 | G19: =IFERROR(E19/F19,"") -> 0.177 | H19: 6505.5 | I19: =IFERROR(H19/E19,"") -> 36.754237 | J19: 1960.3 | K19: =IFERROR(J19/E19,"") -> 11.075141 | L19: 12750 | M19: =L19/H19 -> 1.9598801 | N19: =Q19+T19 -> -10669.96 | O19: =R19+U19 -> 1960.3 | P19: =N19+O19 -> -8709.66 | Q19: =W19*50% -> -5334.98 | R19: =J19*70% -> 1372.21 | S19: =Q19+R19 -> -3962.77 | T19: =Q19 -> -5334.98 | U19: =J19*30% -> 588.09 | V19: =T19+U19 -> -4746.89 | W19: -10669.96
A20: 14 | B20: Jonathan McReynolds | C20: 43537 | D20: =C20 -> 43537 | E20: 447 | F20: 1000 | G20: =IFERROR(E20/F20,"") -> 0.447 | H20: 18410 | I20: =IFERROR(H20/E20,"") -> 41.185682 | J20: 223 | K20: =IFERROR(J20/E20,"") -> 0.49888143 | L20: 8000 | M20: =L20/H20 -> 0.43454644 | N20: =Q20+T20 -> -821.52 | O20: =R20+U20 -> 223 | P20: =N20+O20 -> -598.52 | Q20: =W20*50% -> -410.76 | R20: =J20*70% -> 156.1 | S20: =Q20+R20 -> -254.66 | T20: =Q20 -> -410.76 | U20: =J20*30% -> 66.9 | V20: =T20+U20 -> -343.86 | W20: -821.52
A21: 15 | B21: Arkells | C21: 43539 | D21: =C21 -> 43539 | E21: 1100 | F21: 1100 | G21: =IFERROR(E21/F21,"") -> 1 | H21: 27622 | I21: =IFERROR(H21/E21,"") -> 25.110909 | J21: 12845.26 | K21: =IFERROR(J21/E21,"") -> 11.677509 | L21: 9434.76 | M21: =L21/H21 -> 0.34156687 | N21: =Q21+T21 -> 10248.1 | O21: =R21+U21 -> 12845.26 | P21: =N21+O21 -> 23093.36 | Q21: =W21*50% -> 5124.05 | R21: =J21*70% -> 8991.682 | S21: =Q21+R21 -> 14115.732 | T21: =Q21 -> 5124.05 | U21: =J21*30% -> 3853.578 | V21: =T21+U21 -> 8977.628 | W21: 10248.1
A22: 16 | B22: Big Wild (1) | C22: 43547 | D22: =C22 -> 43547 | E22: 1100 | F22: 1100 | G22: =IFERROR(E22/F22,"") -> 1 | H22: 28174 | I22: =IFERROR(H22/E22,"") -> 25.612727 | J22: 13163.96 | K22: =IFERROR(J22/E22,"") -> 11.967236 | L22: 11980.74 | M22: =IFERROR(L22/H22,"") -> 0.425241 | N22: =Q22+T22 -> 6343.1203 | O22: =R22+U22 -> 13163.96 | P22: =N22+O22 -> 19507.08 | Q22: =W22*33.3333% -> 3171.5602 | R22: =J22*70% -> 9214.772 | S22: =Q22+R22 -> 12386.332 | T22: =Q22 -> 3171.5602 | U22: =J22*30% -> 3949.188 | V22: =T22+U22 -> 7120.7482 | W22: 9514.69
A23: 17 | B23: Sunsquabi (1) | C23: 43553 | D23: =C23 -> 43553 | E23: 484 | F23: 1000 | G23: =IFERROR(E23/F23,"") -> 0.484 | H23: 11243.5 | I23: =IFERROR(H23/E23,"") -> 23.230372 | J23: 7293.28 | K23: =IFERROR(J23/E23,"") -> 15.06876 | L23: 6400 | M23: =IFERROR(L23/H23,"") -> 0.56921777 | N23: =Q23+T23 -> -814.06585 | O23: =R23+U23 -> 7293.28 | P23: =N23+O23 -> 6479.2141 | Q23: =W23*33.3333% -> -407.03293 | R23: =J23*70% -> 5105.296 | S23: =Q23+R23 -> 4698.2631 | T23: =Q23 -> -407.03293 | U23: =J23*30% -> 2187.984 | V23: =T23+U23 -> 1780.9511 | W23: -1221.1
A24: 18 | B24: Failure | C24: 43558 | D24: =C24 -> 43558 | E24: 303 | F24: 1100 | G24: =IFERROR(E24/F24,"") -> 0.27545455 | H24: 11740 | I24: =IFERROR(H24/E24,"") -> 38.745875 | J24: 4399.89 | K24: =IFERROR(J24/E24,"") -> 14.521089 | L24: 15000 | M24: =IFERROR(L24/H24,"") -> 1.2776831 | N24: =Q24+T24 -> -9327.55 | O24: =R24+U24 -> 4399.89 | P24: =N24+O24 -> -4927.66 | Q24: =W24*50% -> -4663.775 | R24: =J24*70% -> 3079.923 | S24: =Q24+R24 -> -1583.852 | T24: =Q24 -> -4663.775 | U24: =J24*30% -> 1319.967 | V24: =T24+U24 -> -3343.808 | W24: -9327.55
A25: 19 | B25: Nils Frahm | C25: 43559 | D25: =C25 -> 43559 | E25: 272 | F25: 1100 | G25: =IFERROR(E25/F25,"") -> 0.24727273 | H25: 9684 | I25: =IFERROR(H25/E25,"") -> 35.602941 | J25: 2241.55 | K25: =IFERROR(J25/E25,"") -> 8.2409926 | L25: 16000 | M25: =IFERROR(L25/H25,"") -> 1.6522098 | N25: =Q25+T25 -> -12042.67 | O25: =R25+U25 -> 2241.55 | P25: =N25+O25 -> -9801.12 | Q25: =W25*50% -> -6021.335 | R25: =J25*70% -> 1569.085 | S25: =Q25+R25 -> -4452.25 | T25: =Q25 -> -6021.335 | U25: =J25*30% -> 672.465 | V25: =T25+U25 -> -5348.87 | W25: -12042.67
A26: 20 | B26: Manic Focus (1) | C26: 43561 | D26: =C26 -> 43561 | E26: 402 | F26: 1100 | G26: =IFERROR(E26/F26,"") -> 0.36545455 | H26: 9729.5 | I26: =IFERROR(H26/E26,"") -> 24.202736 | J26: 7276.94 | K26: =IFERROR(J26/E26,"") -> 18.101841 | L26: 7000 | M26: =IFERROR(L26/H26,"") -> 0.71946143 | N26: =Q26+T26 -> -2002.7113 | O26: =R26+U26 -> 7276.94 | P26: =N26+O26 -> 5274.2287 | Q26: =W26*33.3333% -> -1001.3557 | R26: =J26*70% -> 5093.858 | S26: =Q26+R26 -> 4092.5023 | T26: =Q26 -> -1001.3557 | U26: =J26*30% -> 2183.082 | V26: =T26+U26 -> 1181.7263 | W26: -3004.07
A27: 21 | B27: The Driver Era | C27: 43568 | D27: =C27 -> 43568 | E27: 598 | F27: 1100 | G27: =IFERROR(E27/F27,"") -> 0.54363636 | H27: 25609.5 | I27: =IFERROR(H27/E27,"") -> 42.825251 | J27: 2327.56 | K27: =IFERROR(J27/E27,"") -> 3.8922408 | L27: 12750 | M27: =IFERROR(L27/H27,"") -> 0.49786212 | N27: =Q27+T27 -> -349.51 | O27: =R27+U27 -> 2327.56 | P27: =N27+O27 -> 1978.05 | Q27: =W27*50% -> -174.755 | R27: =J27*70% -> 1629.292 | S27: =Q27+R27 -> 1454.537 | T27: =Q27 -> -174.755 | U27: =J27*30% -> 698.268 | V27: =T27+U27 -> 523.513 | W27: -349.51
A28: 22 | B28: Adam Conover [GUARANTEED] | C28: 43569 | D28: =C28 -> 43569 | G28: =IFERROR(E28/F28,"") | J28: 1430.64 | N28: =Q28+T28 -> 0 | O28: =R28+U28 -> 1430.64 | P28: =N28+O28 -> 1430.64 | R28: =J28*70% -> 1001.448 | S28: =Q28+R28 -> 1001.448 | U28: =J28*30% -> 429.192 | V28: =T28+U28 -> 429.192 | W28: 0
A29: 23 | B29: Swmrs | C29: 43571 | D29: =C29 -> 43571 | E29: 367 | F29: 1000 | G29: =IFERROR(E29/F29,"") -> 0.367 | H29: 9083 | I29: =IFERROR(H29/E29,"") -> 24.749319 | J29: 1685.73 | K29: =IFERROR(J29/E29,"") -> 4.5932698 | L29: 7500 | M29: =IFERROR(L29/H29,"") -> 0.82571837 | N29: =Q29+T29 -> -3464.68 | O29: =R29+U29 -> 1685.73 | P29: =N29+O29 -> -1778.95 | Q29: =W29*50% -> -1732.34 | R29: =J29*70% -> 1180.011 | S29: =Q29+R29 -> -552.329 | T29: =Q29 -> -1732.34 | U29: =J29*30% -> 505.719 | V29: =T29+U29 -> -1226.621 | W29: -3464.68
A30: 24 | B30: Sunn O))) [GUARANTEED] | C30: 43573 | D30: =C30 -> 43573 | G30: =IFERROR(E30/F30,"") | J30: 3274.82 | N30: =Q30+T30 -> 0 | O30: =R30+U30 -> 3274.82 | P30: =N30+O30 -> 3274.82 | R30: =J30*70% -> 2292.374 | S30: =Q30+R30 -> 2292.374 | U30: =J30*30% -> 982.446 | V30: =T30+U30 -> 982.446
A31: 25 | B31: Jai Wolf (1) | C31: 43575 | D31: =C31 -> 43575 | E31: 1100 | F31: 1100 | G31: =IFERROR(E31/F31,"") -> 1 | H31: 27840 | I31: =IFERROR(H31/E31,"") -> 25.309091 | J31: 13062.2 | K31: =IFERROR(J31/E31,"") -> 11.874727 | L31: 12318.93 | M31: =IFERROR(L31/H31,"") -> 0.4424903 | N31: =Q31+T31 -> 5084.6216 | O31: =R31+U31 -> 13062.2 | P31: =N31+O31 -> 18146.822 | Q31: =W31*33.3333% -> 2542.3108 | R31: =J31*70% -> 9143.54 | S31: =Q31+R31 -> 11685.851 | T31: =Q31 -> 2542.3108 | U31: =J31*30% -> 3918.66 | V31: =T31+U31 -> 6460.9708 | W31: 7626.94
A32: 26 | B32: Neko Case | C32: 43577 | D32: =C32 -> 43577 | E32: 674 | F32: 1100 | G32: =IFERROR(E32/F32,"") -> 0.61272727 | H32: 24059.5 | I32: =IFERROR(H32/E32,"") -> 35.696588 | J32: 6679.44 | K32: =IFERROR(J32/E32,"") -> 9.9101484 | L32: 19000 | M32: =IFERROR(L32/H32,"") -> 0.78970885 | N32: =Q32+T32 -> -1867.24 | O32: =R32+U32 -> 6679.44 | P32: =N32+O32 -> 4812.2 | Q32: =W32*50% -> -933.62 | R32: =J32*70% -> 4675.608 | S32: =Q32+R32 -> 3741.988 | T32: =Q32 -> -933.62 | U32: =J32*30% -> 2003.832 | V32: =T32+U32 -> 1070.212 | W32: -1867.24
A33: 27 | B33: Bad Suns | C33: 43580 | D33: =C33 -> 43580 | E33: 689 | F33: 1100 | G33: =IFERROR(E33/F33,"") -> 0.62636364 | H33: 19549.5 | I33: =IFERROR(H33/E33,"") -> 28.37373 | J33: 3714.44 | K33: =IFERROR(J33/E33,"") -> 5.3910595 | L33: 15400 | M33: =IFERROR(L33/H33,"") -> 0.78774393 | N33: =Q33+T33 -> -2116.45 | O33: =R33+U33 -> 3714.44 | P33: =N33+O33 -> 1597.99 | Q33: =W33*50% -> -1058.225 | R33: =J33*70% -> 2600.108 | S33: =Q33+R33 -> 1541.883 | T33: =Q33 -> -1058.225 | U33: =J33*30% -> 1114.332 | V33: =T33+U33 -> 56.107 | W33: -2116.45
A34: 28 | B34: Claypool Lennon Delerium | C34: 43582 | D34: =C34 -> 43582 | E34: 1100 | F34: 1100 | G34: =IFERROR(E34/F34,"") -> 1 | H34: 50826 | I34: =IFERROR(H34/E34,"") -> 46.205455 | J34: 14217.94 | K34: =IFERROR(J34/E34,"") -> 12.9254 | L34: 15500 | M34: =IFERROR(L34/H34,"") -> 0.30496203 | N34: =Q34+T34 -> 13945.74 | O34: =R34+U34 -> 14217.94 | P34: =N34+O34 -> 28163.68 | Q34: =W34*50% -> 6972.87 | R34: =J34*70% -> 9952.558 | S34: =Q34+R34 -> 16925.428 | T34: =Q34 -> 6972.87 | U34: =J34*30% -> 4265.382 | V34: =T34+U34 -> 11238.252 | W34: 13945.74
A35: 29 | B35: Ann Marie | C35: 43583 | D35: =C35 -> 43583 | E35: 257 | F35: 1000 | G35: =IFERROR(E35/F35,"") -> 0.257 | H35: 9478 | I35: =IFERROR(H35/E35,"") -> 36.879377 | J35: 1363.61 | K35: =IFERROR(J35/E35,"") -> 5.3058755 | L35: 3900 | M35: =IFERROR(L35/H35,"") -> 0.41147922 | N35: =Q35+T35 -> -2032.41 | O35: =R35+U35 -> 1363.61 | P35: =N35+O35 -> -668.8 | Q35: =W35*50% -> -1016.205 | R35: =J35*70% -> 954.527 | S35: =Q35+R35 -> -61.678 | T35: =Q35 -> -1016.205 | U35: =J35*30% -> 409.083 | V35: =T35+U35 -> -607.122 | W35: -2032.41
A36: 30 | B36: Turnover | C36: 43588 | D36: =C36 -> 43588 | E36: 914 | F36: 1100 | G36: =IFERROR(E36/F36,"") -> 0.83090909 | H36: 28549.5 | I36: =IFERROR(H36/E36,"") -> 31.235777 | J36: 9555.76 | K36: =IFERROR(J36/E36,"") -> 10.45488 | L36: 17500 | M36: =IFERROR(L36/H36,"") -> 0.61297045 | N36: =Q36+T36 -> 3622.75 | O36: =R36+U36 -> 9555.76 | P36: =N36+O36 -> 13178.51 | Q36: =W36*50% -> 1811.375 | R36: =J36*70% -> 6689.032 | S36: =Q36+R36 -> 8500.407 | T36: =Q36 -> 1811.375 | U36: =J36*30% -> 2866.728 | V36: =T36+U36 -> 4678.103 | W36: 3622.75
A37: 31 | B37: Higher Brothers | C37: 43594 | D37: =C37 -> 43594 | E37: 194 | F37: 1000 | G37: =IFERROR(E37/F37,"") -> 0.194 | H37: 8312.5 | I37: =IFERROR(H37/E37,"") -> 42.847938 | J37: 1412.04 | K37: =IFERROR(J37/E37,"") -> 7.2785567 | L37: 10500 | M37: =IFERROR(L37/H37,"") -> 1.2631579 | N37: =Q37+T37 -> -10415.5 | O37: =R37+U37 -> 1412.04 | P37: =N37+O37 -> -9003.46 | Q37: =W37*50% -> -5207.75 | R37: =J37*70% -> 988.428 | S37: =Q37+R37 -> -4219.322 | T37: =Q37 -> -5207.75 | U37: =J37*30% -> 423.612 | V37: =T37+U37 -> -4784.138 | W37: -10415.5
A38: 32 | B38: Andy Black | C38: 43596 | D38: =C38 -> 43596 | E38: 358 | F38: 1100 | G38: =IFERROR(E38/F38,"") -> 0.32545455 | H38: 11466.5 | I38: =IFERROR(H38/E38,"") -> 32.02933 | J38: 1403.19 | K38: =IFERROR(J38/E38,"") -> 3.9195251 | L38: 12150 | M38: =IFERROR(L38/H38,"") -> 1.0596084 | N38: =Q38+T38 -> -8341.48 | O38: =R38+U38 -> 1403.19 | P38: =N38+O38 -> -6938.29 | Q38: =W38*50% -> -4170.74 | R38: =J38*70% -> 982.233 | S38: =Q38+R38 -> -3188.507 | T38: =Q38 -> -4170.74 | U38: =J38*30% -> 420.957 | V38: =T38+U38 -> -3749.783 | W38: -8341.48
A39: 33 | B39: Gretchen Rubin | C39: 43600 | D39: =C39 -> 43600 | E39: 337 | F39: 400 | G39: =IFERROR(E39/F39,"") -> 0.8425 | H39: 16489 | I39: =IFERROR(H39/E39,"") -> 48.928783 | J39: 1249.94 | K39: =IFERROR(J39/E39,"") -> 3.7090208 | L39: 4419.37 | M39: =IFERROR(L39/H39,"") -> 0.26801929 | N39: =Q39+T39 -> 5448.47 | O39: =R39+U39 -> 1249.94 | P39: =N39+O39 -> 6698.41 | Q39: =W39*50% -> 2724.235 | R39: =J39*70% -> 874.958 | S39: =Q39+R39 -> 3599.193 | T39: =Q39 -> 2724.235 | U39: =J39*30% -> 374.982 | V39: =T39+U39 -> 3099.217 | W39: 5448.47
A40: 34 | B40: FKJ (1) | C40: 43601 | D40: =C40 -> 43601 | E40: 1100 | F40: 1100 | G40: =IFERROR(E40/F40,"") -> 1 | H40: 30495 | I40: =IFERROR(H40/E40,"") -> 27.722727 | J40: 13512.85 | K40: =IFERROR(J40/E40,"") -> 12.284409 | L40: 13506.58 | M40: =IFERROR(L40/H40,"") -> 0.4429113 | N40: =Q40+T40 -> 6448.9269 | O40: =R40+U40 -> 13512.85 | P40: =N40+O40 -> 19961.777 | Q40: =W40*33.3333% -> 3224.4634 | R40: =J40*70% -> 9458.995 | S40: =Q40+R40 -> 12683.458 | T40: =Q40 -> 3224.4634 | U40: =J40*30% -> 4053.855 | V40: =T40+U40 -> 7278.3184 | W40: 9673.4 | X40: 9673.4 | Y40: -3224.47
A41: 35 | B41: Movements | C41: 43602 | D41: =C41 -> 43602 | E41: 654 | F41: 1100 | G41: =IFERROR(E41/F41,"") -> 0.59454545 | H41: 17853.5 | I41: =IFERROR(H41/E41,"") -> 27.29893 | J41: 6010.96 | K41: =IFERROR(J41/E41,"") -> 9.1910703 | L41: 12000 | M41: =IFERROR(L41/H41,"") -> 0.67213712 | N41: =Q41+T41 -> 928.94 | O41: =R41+U41 -> 6010.96 | P41: =N41+O41 -> 6939.9 | Q41: =W41*50% -> 464.47 | R41: =J41*70% -> 4207.672 | S41: =Q41+R41 -> 4672.142 | T41: =Q41 -> 464.47 | U41: =J41*30% -> 1803.288 | V41: =T41+U41 -> 2267.758 | W41: 928.94
...

Sheet Magic Stick
O1: VENUE TOTAL | R1: PARTNER SPLIT
B2: ***MAGIC STICK RESULTS*** | O2: MAGIC STICK | R2: MTC, Inc. | U2: J&A
B3: Name | C3: Promoter Code | D3: Date | E3: Day of the week | F3: Tickets Sold | G3: Venue Capacity | H3: Capacity Rate | I3: Gross Ticket Revenue | J3: Avg. Ticket Price (including TW rebate) | K3: Bar Revenue | L3: Avg sale of alcohol per guest | M3: Band(s) guarantee | N3: % of Gross Ticket Revenue | O3: Gate Settlement Gain/(Loss) | P3: Bar Sales - 100% | Q3: Show Gross Proceeds (before COGS, Labor, & Facility Costs) | R3: Gate Settlement Gain/(Loss) | S3: Bar Sales - 50% | T3: Show Gross Proceeds (before COGS, Labor, & Facility Costs) | U3: Gate Settlement Gain/(Loss) | V3: Bar Sales - 50% | W3: Show Gross Proceeds (before COGS, Labor, & Facility Costs) | X3: INPUT - Total Gate Settlement | AA3: Facility Fee & Rebate | AB3: React per person promoter fees
B4: TOTALS | F4: =SUM(F7:F82) -> 28952 | G4: =SUM(G7:G82) -> 43700 | I4: =SUM(I7:I82) -> 754923 | K4: =SUM(K7:K82) -> 523492.54 | M4: =SUM(M7:M82) -> 456312.56 | N4: =SUM(N7:N82) -> 43.154911 | O4: =SUM(O7:O82) -> 31502.43 | P4: =SUM(P7:P82) -> 523492.54 | Q4: =SUM(Q7:Q82) -> 554994.97 | R4: =SUM(R7:R82) -> 15751.215 | S4: =SUM(S7:S82) -> 261746.27 | T4: =SUM(T7:T82) -> 277497.49 | ... W4: =SUM(W7:W82) -> 277497.49
B5: AVERAGES | F5: =F4/COUNTA(F7:F82) -> 482.53333 | G5: =G4/COUNTA(G7:G82) -> 728.33333 | H5: =F4/G4 -> 0.66251716 | I5: =I4/COUNTA(I7:I82) -> 12582.05 | J5: =I4/F4 -> 26.074986 | K5: =K4/COUNTA(K7:K82) -> 8581.8449 | L5: =K4/F4 -> 18.081395 | M5: =M4/COUNTA(M7:M82) -> 7605.2093 | N5: =M4/I4 -> 0.60444914 | O5: =O4/COUNTA(O7:O82) -> 516.43328 | P5: =P4/COUNTA(P7:P82) -> 8581.8449 | Q5: =Q4/COUNTA(Q7:Q82) -> 9098.2782 | R5: =R4/COUNTA(R7:R82) -> 258.21664 | S5: =S4/COUNTA(S7:S82) -> 4290.9225 | T5: =T4/COUNTA(T7:T82) -> 4549.1391 | U5: =U4/COUNTA(U7:U82) -> 258.21664 | V5: =V4/COUNTA(V7:V82) -> 4290.9225 | W5: =W4/COUNTA(W7:W82) -> 4549.1391
A7: 1 | B7: Will Sessions | C7: 1 | D7: 43491 | E7: =D7 -> 43491 | F7: 270 | G7: 700 | H7: =IFERROR(F7/G7,"") -> 0.38571429 | I7: 4193 | J7: =IFERROR(I7/F7,"") -> 15.52963 | K7: 5772 | L7: =IFERROR(K7/F7,"") -> 21.377778 | M7: 3300 | N7: =IFERROR(M7/I7,"") -> 0.787026 | O7: =R7+U7 -> -278 | P7: =S7+V7 -> 5772 | Q7: =O7+P7 -> 5494 | R7: =X7*50% -> -139 | S7: =K7*50% -> 2886 | T7: =R7+S7 -> 2747 | U7: =R7 -> -139 | V7: =K7*50% -> 2886 | W7: =U7+V7 -> 2747 | X7: -278 | Y7: =T7+W7 -> 5494
A8: 2 | B8: Claude VonStroke - Night 1 | C8: 5 | D8: 43504 | E8: =D8 -> 43504 | F8: 800 | G8: 800 | H8: =IFERROR(F8/G8,"") -> 1 | I8: 27370.5 | J8: =IFERROR(I8/F8,"") -> 34.213125 | K8: 18143 | L8: =IFERROR(K8/F8,"") -> 22.67875 | M8: 15400 | N8: =IFERROR(M8/I8,"") -> 0.56264957 | O8: =R8+U8 -> 5503.13 | P8: =S8+V8 -> 18143 | Q8: =O8+P8 -> 23646.13 | R8: =X8*50% -> 2751.565 | S8: =K8*50% -> 9071.5 | T8: =R8+S8 -> 11823.065 | U8: =R8 -> 2751.565 | V8: =K8*50% -> 9071.5 | W8: =U8+V8 -> 11823.065 | X8: 5503.13 | Y8: =T8+W8 -> 23646.13
A9: 3 | B9: Claude VonStroke - Night 2 | C9: 5 | D9: 43505 | E9: =D9 -> 43505 | F9: 810 | G9: 800 | H9: =IFERROR(F9/G9,"") -> 1.0125 | I9: 26875 | J9: =IFERROR(I9/F9,"") -> 33.179012 | K9: 21111.5 | L9: =IFERROR(K9/F9,"") -> 26.06358 | M9: =15000+125+100+150+75 -> 15450 | N9: =IFERROR(M9/I9,"") -> 0.57488372 | O9: =R9+U9 -> 6280.05 | P9: =S9+V9 -> 21111.5 | Q9: =O9+P9 -> 27391.55 | R9: =X9*50% -> 3140.025 | S9: =K9*50% -> 10555.75 | T9: =R9+S9 -> 13695.775 | U9: =R9 -> 3140.025 | V9: =K9*50% -> 10555.75 | W9: =U9+V9 -> 13695.775 | X9: 6280.05 | Y9: =T9+W9 -> 27391.55
A10: 4 | B10: Omega moos | C10: 5 | D10: 43518 | E10: =D10 -> 43518 | F10: 734 | G10: 700 | H10: =IFERROR(F10/G10,"") -> 1.0485714 | I10: 13853.5 | J10: =IFERROR(I10/F10,"") -> 18.873978 | K10: 9304 | L10: =IFERROR(K10/F10,"") -> 12.675749 | M10: 10150 | N10: =IFERROR(M10/I10,"") -> 0.73266684 | O10: =R10+U10 -> 1014.45 | P10: =S10+V10 -> 9304 | Q10: =O10+P10 -> 10318.45 | R10: =X10*50% -> 507.225 | S10: =K10*50% -> 4652 | T10: =R10+S10 -> 5159.225 | U10: =R10 -> 507.225 | V10: =K10*50% -> 4652 | W10: =U10+V10 -> 5159.225 | X10: 1014.45 | Y10: =T10+W10 -> 10318.45
A11: 5 | B11: Desert Hearts | C11: 5 | D11: 43519 | E11: =D11 -> 43519 | F11: 806 | G11: 700 | H11: =IFERROR(F11/G11,"") -> 1.1514286 | I11: 20546 | J11: =IFERROR(I11/F11,"") -> 25.491315 | K11: 17568 | L11: =IFERROR(K11/F11,"") -> 21.796526 | M11: 9525 | N11: =IFERROR(M11/I11,"") -> 0.46359389 | O11: =R11+U11 -> 4143.68 | P11: =S11+V11 -> 17568 | Q11: =O11+P11 -> 21711.68 | R11: =X11*50% -> 2071.84 | S11: =K11*50% -> 8784 | T11: =R11+S11 -> 10855.84 | U11: =R11 -> 2071.84 | V11: =K11*50% -> 8784 | W11: =U11+V11 -> 10855.84 | X11: 4143.68 | Y11: =T11+W11 -> 21711.68
A12: 6 | B12: Marco Carola | C12: 5 | D12: 43532 | E12: =D12 -> 43532 | F12: 510 | G12: 700 | H12: =IFERROR(F12/G12,"") -> 0.72857143 | I12: 16440 | J12: =IFERROR(I12/F12,"") -> 32.235294 | K12: 17184 | L12: =IFERROR(K12/F12,"") -> 33.694118 | M12: 18500 | N12: =IFERROR(M12/I12,"") -> 1.1253041 | O12: =R12+U12 -> -7036.43 | P12: =S12+V12 -> 17184 | Q12: =O12+P12 -> 10147.57 | R12: =X12*50% -> -3518.215 | S12: =K12*50% -> 8592 | T12: =R12+S12 -> 5073.785 | U12: =R12 -> -3518.215 | V12: =K12*50% -> 8592 | W12: =U12+V12 -> 5073.785 | X12: -7036.43 | Y12: =T12+W12 -> 10147.57
A13: 7 | B13: Charlesthefirst | C13: 5 | D13: 43533 | E13: =D13 -> 43533 | F13: 800 | G13: 800 | H13: =IFERROR(F13/G13,"") -> 1 | I13: 14620 | J13: =IFERROR(I13/F13,"") -> 18.275 | K13: 12599 | L13: =IFERROR(K13/F13,"") -> 15.74875 | M13: 8100 | N13: =IFERROR(M13/I13,"") -> 0.55403557 | O13: =R13+U13 -> 1590.67 | P13: =S13+V13 -> 12599 | Q13: =O13+P13 -> 14189.67 | R13: =X13*50% -> 795.335 | S13: =K13*50% -> 6299.5 | T13: =R13+S13 -> 7094.835 | U13: =R13 -> 795.335 | V13: =K13*50% -> 6299.5 | W13: =U13+V13 -> 7094.835 | X13: 1590.67 | Y13: =T13+W13 -> 14189.67
A14: 8 | B14: Desert Dwellers | C14: 8 | D14: 43547 | E14: =D14 -> 43547 | F14: 753 | G14: 700 | H14: =IFERROR(F14/G14,"") -> 1.0757143 | I14: 19105 | J14: =IFERROR(I14/F14,"") -> 25.371846 | K14: 10559 | L14: =IFERROR(K14/F14,"") -> 14.022576 | M14: 6050 | N14: =IFERROR(M14/I14,"") -> 0.31667103 | O14: =R14+U14 -> 10383.67 | P14: =S14+V14 -> 10559 | Q14: =O14+P14 -> 20942.67 | R14: =X14*50% -> 5191.835 | S14: =K14*50% -> 5279.5 | T14: =R14+S14 -> 10471.335 | U14: =R14 -> 5191.835 | V14: =K14*50% -> 5279.5 | W14: =U14+V14 -> 10471.335 | X14: 10383.67 | Y14: =T14+W14 -> 20942.67
A15: 9 | B15: Charlotte de Witte | C15: 5 | D15: 43553 | E15: =D15 -> 43553 | F15: 846 | G15: 800 | H15: =IFERROR(F15/G15,"") -> 1.0575 | I15: 21440 | J15: =IFERROR(I15/F15,"") -> 25.34279 | K15: 16341 | L15: =IFERROR(K15/F15,"") -> 19.315603 | M15: 10700 | N15: =IFERROR(M15/I15,"") -> 0.49906716 | O15: =R15+U15 -> 5607.96 | P15: =S15+V15 -> 16341 | Q15: =O15+P15 -> 21948.96 | R15: =X15*50% -> 2803.98 | S15: =K15*50% -> 8170.5 | T15: =R15+S15 -> 10974.48 | U15: =R15 -> 2803.98 | V15: =K15*50% -> 8170.5 | W15: =U15+V15 -> 10974.48 | X15: 5607.96 | Y15: =T15+W15 -> 21948.96
A16: 10 | B16: The True Blue [RENTAL] | C16: 6 | D16: 43554 | E16: =D16 -> 43554 | H16: =IFERROR(F16/G16,"") | J16: =IFERROR(I16/F16,"") | K16: 2361 | L16: =IFERROR(K16/F16,"") | N16: =IFERROR(M16/I16,"") | O16: =R16+U16 -> -120 | P16: =S16+V16 -> 2361 | Q16: =O16+P16 -> 2241 | R16: =X16*50% -> -60 | S16: =K16*50% -> 1180.5 | T16: =R16+S16 -> 1120.5 | U16: =R16 -> -60 | V16: =K16*50% -> 1180.5 | W16: =U16+V16 -> 1120.5 | X16: -120 | Y16: =T16+W16 -> 2241
A17: 11 | B17: Droeloe | C17: 2 | D17: 43560 | E17: =D17 -> 43560 | F17: 736 | G17: 700 | H17: =IFERROR(F17/G17,"") -> 1.0514286 | I17: =11870+AA17 -> 14230 | J17: =IFERROR(I17/F17,"") -> 19.334239 | K17: 9681 | L17: =IFERROR(K17/F17,"") -> 13.153533 | M17: 6152.7 | N17: =IFERROR(M17/I17,"") -> 0.43237526 | O17: =R17+U17 -> 1320.98 | P17: =S17+V17 -> 9681 | Q17: =O17+P17 -> 11001.98 | R17: =(X17+AA17-AB17)/2 -> 660.49 | S17: =K17*50% -> 4840.5 | T17: =R17+S17 -> 5500.99 | U17: =R17 -> 660.49 | V17: =K17*50% -> 4840.5 | W17: =U17+V17 -> 5500.99 | X17: 1168.98 | Y17: =T17+W17 -> 11001.98 | AA17: =560+1800 -> 2360 | AB17: 2208
A18: 12 | B18: Crankdat | C18: 2 | D18: 43568 | E18: =D18 -> 43568 | F18: 442 | G18: 700 | H18: =IFERROR(F18/G18,"") -> 0.63142857 | I18: =7755+AA18 -> 9066 | J18: =IFERROR(I18/F18,"") -> 20.511312 | K18: 7513.5 | L18: =IFERROR(K18/F18,"") -> 16.998869 | M18: =1250+2000+750+400+175 -> 4575 | N18: =IFERROR(M18/I18,"") -> 0.50463269 | O18: =R18+U18 -> -571.79 | P18: =S18+V18 -> 7513.5 | Q18: =O18+P18 -> 6941.71 | R18: =(X18+AA18-AB18)/2 -> -285.895 | S18: =K18*50% -> 3756.75 | T18: =R18+S18 -> 3470.855 | U18: =R18 -> -285.895 | V18: =K18*50% -> 3756.75 | W18: =U18+V18 -> 3470.855 | X18: -556.79 | Y18: =T18+W18 -> 6941.71 | AA18: =291+1020 -> 1311 | AB18: 1326
A19: 13 | B19: Esseks | C19: 8 | D19: 43574 | E19: =D19 -> 43574 | F19: 462 | G19: 700 | H19: =IFERROR(F19/G19,"") -> 0.66 | I19: 7541 | J19: =IFERROR(I19/F19,"") -> 16.322511 | K19: 7542.5 | L19: =IFERROR(K19/F19,"") -> 16.325758 | M19: 5000 | N19: =IFERROR(M19/I19,"") -> 0.66304204 | O19: =R19+U19 -> 3430.92 | P19: =S19+V19 -> 7542.5 | Q19: =O19+P19 -> 10973.42 | R19: =X19*50% -> 1715.46 | S19: =K19*50% -> 3771.25 | T19: =R19+S19 -> 5486.71 | U19: =R19 -> 1715.46 | V19: =K19*50% -> 3771.25 | W19: =U19+V19 -> 5486.71 | X19: =SUM(Z19:AA19)-6480.58-AB19 -> 3430.92 | Y19: =T19+W19 -> 10973.42 | Z19: =3050+5515 -> 8565 | AA19: =1055.5+291 -> 1346.5 | AB19: 0
A20: 14 | B20: CloZee | C20: 2 | D20: 43581 | E20: =D20 -> 43581 | F20: 800 | G20: 800 | H20: =IFERROR(F20/G20,"") -> 1 | I20: =23036+AA20 -> 27047 | J20: =IFERROR(I20/F20,"") -> 33.80875 | K20: 14724 | L20: =IFERROR(K20/F20,"") -> 18.405 | M20: =10440.5+1000+250+500 -> 12190.5 | N20: =IFERROR(M20/I20,"") -> 0.45071542 | O20: =R20+U20 -> 4239.72 | P20: =S20+V20 -> 14724 | Q20: =O20+P20 -> 18963.72 | R20: =X20*50% -> 2119.86 | S20: =K20*50% -> 7362 | T20: =R20+S20 -> 9481.86 | U20: =R20 -> 2119.86 | V20: =K20*50% -> 7362 | W20: =U20+V20 -> 9481.86 | X20: =SUM(Z20:AA20)-16396.28-AB20 -> 4239.72 | Y20: =T20+W20 -> 18963.72 | Z20: =75+18950 -> 19025 | AA20: =2889+642+480 -> 4011 | AB20: 2400 | AC20: =1276.86*2 -> 2553.72 | AD20: =AC20+AA20 -> 6564.72 | AE20: =AD20/2 -> 3282.36
A21: 15 | B21: Freddy Todd | C21: 2 | D21: 43589 | E21: =D21 -> 43589 | F21: 436 | G21: 700 | H21: =IFERROR(F21/G21,"") -> 0.62285714 | I21: =7595+AA21 -> 8460 | J21: =IFERROR(I21/F21,"") -> 19.40367 | K21: 5650 | L21: =IFERROR(K21/F21,"") -> 12.958716 | M21: 4550 | N21: =IFERROR(M21/I21,"") -> 0.53782506 | O21: =R21+U21 -> -2461.48 | P21: =S21+V21 -> 5650 | Q21: =O21+P21 -> 3188.52 | R21: =(X21+AA21-AB21)/2 -> -1230.74 | S21: =K21*50% -> 2825 | T21: =R21+S21 -> 1594.26 | U21: =R21 -> -1230.74 | V21: =K21*50% -> 2825 | W21: =U21+V21 -> 1594.26 | X21: -2336.48 | Y21: =T21+W21 -> 3188.52 | AA21: =687+178 -> 865 | AB21: 990
A22: 16 | B22: Cursive/Mewithoutyou | C22: 1 | D22: 43594 | E22: =D22 -> 43594 | F22: 401 | G22: 700 | H22: =IFERROR(F22/G22,"") -> 0.57285714 | I22: 11236 | J22: =IFERROR(I22/F22,"") -> 28.01995 | K22: 4843 | L22: =IFERROR(K22/F22,"") -> 12.077307 | M22: =4000+4000+500 -> 8500 | N22: =IFERROR(M22/I22,"") -> 0.75649697 | O22: =R22+U22 -> -50.71 | P22: =S22+V22 -> 4843 | Q22: =O22+P22 -> 4792.29 | R22: =X22*50% -> -25.355 | S22: =K22*50% -> 2421.5 | T22: =R22+S22 -> 2396.145 | U22: =R22 -> -25.355 | V22: =K22*50% -> 2421.5 | W22: =U22+V22 -> 2396.145 | X22: -50.71 | Y22: =T22+W22 -> 4792.29 | AB22: 23036
A23: 17 | B23: Riverside | C23: 1 | D23: 43603 | E23: =D23 -> 43603 | F23: 267 | G23: 700 | H23: =IFERROR(F23/G23,"") -> 0.38142857 | I23: 7096.75 | J23: =IFERROR(I23/F23,"") -> 26.579588 | K23: 2405 | L23: =IFERROR(K23/F23,"") -> 9.0074906 | M23: 5000 | N23: =IFERROR(M23/I23,"") -> 0.70454786 | O23: =R23+U23 -> -409.25 | P23: =S23+V23 -> 2405 | Q23: =O23+P23 -> 1995.75 | R23: =X23*50% -> -204.625 | S23: =K23*50% -> 1202.5 | T23: =R23+S23 -> 997.875 | U23: =R23 -> -204.625 | V23: =K23*50% -> 1202.5 | W23: =U23+V23 -> 997.875 | X23: =-1129.25+720 -> -409.25 | Y23: =T23+W23 -> 1995.75 | AB23: -16396.28
A24: 18 | B24: Snow Tha Product | C24: 4 | D24: 43607 | E24: =D24 -> 43607 | F24: 637 | G24: 700 | H24: =IFERROR(F24/G24,"") -> 0.91 | I24: 16427 | J24: =IFERROR(I24/F24,"") -> 25.788069 | K24: 9143 | L24: =IFERROR(K24/F24,"") -> 14.353218 | M24: =3729.16+3000+100 -> 6829.16 | N24: =IFERROR(M24/I24,"") -> 0.41572777 | O24: =R24+U24 -> 6103.47 | P24: =S24+V24 -> 9143 | Q24: =O24+P24 -> 15246.47 | R24: =X24*50% -> 3051.735 | S24: =K24*50% -> 4571.5 | T24: =R24+S24 -> 7623.235 | U24: =R24 -> 3051.735 | V24: =K24*50% -> 4571.5 | W24: =U24+V24 -> 7623.235 | X24: =6103.47 -> 6103.47 | Y24: =T24+W24 -> 15246.47
A25: 19 | B25: Walker And Royce | C25: 5 | D25: 43609 | E25: =D25 -> 43609 | F25: 829 | G25: 800 | H25: =IFERROR(F25/G25,"") -> 1.03625 | I25: 24387.5 | J25: =IFERROR(I25/F25,"") -> 29.417973 | K25: 22313.5 | L25: =IFERROR(K25/F25,"") -> 26.916164 | M25: 11725 | N25: =IFERROR(M25/I25,"") -> 0.48077909 | O25: =R25+U25 -> 5411.33 | P25: =S25+V25 -> 22313.5 | Q25: =O25+P25 -> 27724.83 | R25: =X25*50% -> 2705.665 | S25: =K25*50% -> 11156.75 | T25: =R25+S25 -> 13862.415 | U25: =R25 -> 2705.665 | V25: =K25*50% -> 11156.75 | W25: =U25+V25 -> 13862.415 | X25: 5411.33 | Y25: =T25+W25 -> 27724.83 | AB25: -2400
A26: 20 | B26: Detroit Love | C26: 5 | D26: 43610 | E26: =D26 -> 43610 | F26: 844 | G26: 800 | H26: =IFERROR(F26/G26,"") -> 1.055 | I26: 31245.5 | J26: =IFERROR(I26/F26,"") -> 37.020735 | K26: 15188.5 | L26: =IFERROR(K26/F26,"") -> 17.995853 | M26: 15000 | N26: =IFERROR(M26/I26,"") -> 0.48006913 | O26: =R26+U26 -> 9483.94 | P26: =S26+V26 -> 15188.5 | Q26: =O26+P26 -> 24672.44 | R26: =X26*50% -> 4741.97 | S26: =K26*50% -> 7594.25 | T26: =R26+S26 -> 12336.22 | U26: =R26 -> 4741.97 | V26: =K26*50% -> 7594.25 | W26: =U26+V26 -> 12336.22 | X26: 9483.94 | Y26: =T26+W26 -> 24672.44 | AB26: =AB22+AB23+AB25 -> 4239.72
A27: 21 | B27: Origins | C27: 5 | D27: 43611 | E27: =D27 -> 43611 | F27: 823 | G27: 800 | H27: =IFERROR(F27/G27,"") -> 1.02875 | I27: 29160.5 | J27: =IFERROR(I27/F27,"") -> 35.431956 | K27: 13424.5 | L27: =IFERROR(K27/F27,"") -> 16.311665 | M27: 12000 | N27: =IFERROR(M27/I27,"") -> 0.41151558 | O27: =R27+U27 -> 10680.97 | P27: =S27+V27 -> 13424.5 | Q27: =O27+P27 -> 24105.47 | R27: =X27*50% -> 5340.485 | S27: =K27*50% -> 6712.25 | T27: =R27+S27 -> 12052.735 | U27: =R27 -> 5340.485 | V27: =K27*50% -> 6712.25 | W27: =U27+V27 -> 12052.735 | X27: 10680.97 | Y27: =T27+W27 -> 24105.47 | AB27: =AB26/2 -> 2119.86
A28: 22 | B28: Repopulate Mars | C28: 5 | D28: 43612 | E28: =D28 -> 43612 | F28: 919 | G28: 800 | H28: =IFERROR(F28/G28,"") -> 1.14875 | I28: 33122 | J28: =IFERROR(I28/F28,"") -> 36.041349 | K28: 14128.5 | L28: =IFERROR(K28/F28,"") -> 15.373776 | M28: 12500 | N28: =IFERROR(M28/I28,"") -> 0.37739267 | O28: =R28+U28 -> 13403.32 | P28: =S28+V28 -> 14128.5 | Q28: =O28+P28 -> 27531.82 | R28: =X28*50% -> 6701.66 | S28: =K28*50% -> 7064.25 | T28: =R28+S28 -> 13765.91 | U28: =R28 -> 6701.66 | V28: =K28*50% -> 7064.25 | W28: =U28+V28 -> 13765.91 | X28: 13403.32 | Y28: =T28+W28 -> 27531.82
A29: 23 | B29: Goopsteppa [partial free tixs] | C29: 8 | D29: 43617 | E29: =D29 -> 43617 | F29: 252 | G29: 800 | H29: =IFERROR(F29/G29,"") -> 0.315 | I29: 2162.5 | J29: =IFERROR(I29/F29,"") -> 8.5813492 | K29: 3595 | L29: =IFERROR(K29/F29,"") -> 14.265873 | M29: =1250+425 -> 1675 | N29: =IFERROR(M29/I29,"") -> 0.77456647 | O29: =R29+U29 -> -1164.66 | P29: =S29+V29 -> 3595 | Q29: =O29+P29 -> 2430.34 | R29: =X29*50% -> -582.33 | S29: =K29*50% -> 1797.5 | T29: =R29+S29 -> 1215.17 | U29: =R29 -> -582.33 | V29: =K29*50% -> 1797.5 | W29: =U29+V29 -> 1215.17 | X29: -1164.66 | Y29: =T29+W29 -> 2430.34
A30: 24 | B30: If Walls Could Talk [band rental] | C30: 5 | D30: 43631 | E30: =D30 -> 43631 | F30: 286 | G30: 600 | H30: =IFERROR(F30/G30,"") -> 0.47666667 | I30: =780 -> 780 | J30: =IFERROR(I30/F30,"") -> 2.7272727 | K30: 2748 | L30: =IFERROR(K30/F30,"") -> 9.6083916 | M30: 0 | N30: =IFERROR(M30/I30,"") -> 0 | O30: =R30+U30 -> -383 | P30: =S30+V30 -> 2748 | Q30: =O30+P30 -> 2365 | R30: =X30*50% -> -191.5 | S30: =K30*50% -> 1374 | T30: =R30+S30 -> 1182.5 | U30: =R30 -> -191.5 | V30: =K30*50% -> 1374 | W30: =U30+V30 -> 1182.5 | X30: -383 | Y30: =T30+W30 -> 2365
A31: 25 | B31: Dub Down | C31: 1 | D31: 43659 | E31: =D31 -> 43659 | F31: 329 | G31: 700 | H31: =IFERROR(F31/G31,"") -> 0.47 | I31: 6575 | J31: =IFERROR(I31/F31,"") -> 19.984802 | K31: 5856 | L31: =IFERROR(K31/F31,"") -> 17.799392 | M31: =1250+1000+1000+1000+400 -> 4650 | N31: =IFERROR(M31/I31,"") -> 0.70722433 | O31: =R31+U31 -> -1431.28 | P31: =S31+V31 -> 5856 | Q31: =O31+P31 -> 4424.72 | R31: =X31*50% -> -715.64 | S31: =K31*50% -> 2928 | T31: =R31+S31 -> 2212.36 | U31: =R31 -> -715.64 | V31: =K31*50% -> 2928 | W31: =U31+V31 -> 2212.36 | X31: -1431.28 | Y31: =T31+W31 -> 4424.72
A32: 26 | B32: Louis Prima Jr. | C32: 3 | D32: 43671 | E32: =D32 -> 43671 | F32: 46 | G32: 700 | H32: =IFERROR(F32/G32,"") -> 0.065714286 | I32: =1020+98.5 -> 1118.5 | J32: =IFERROR(I32/F32,"") -> 24.315217 | K32: 317.9 | L32: =IFERROR(K32/F32,"") -> 6.9108696 | M32: 1500 | N32: =IFERROR(M32/I32,"") -> 1.3410818 | O32: =R32+U32 -> -2073.41 | P32: =S32+V32 -> 317.9 | Q32: =O32+P32 -> -1755.51 | R32: =(X32+AA32-AB32)*50% -> -1036.705 | S32: =K32*50% -> 158.95 | T32: =R32+S32 -> -877.755 | U32: =R32 -> -1036.705 | V32: =K32*50% -> 158.95 | W32: =U32+V32 -> -877.755 | X32: -2171.91 | Y32: =T32+W32 -> -1755.51 | AA32: 98.5 | AD32: =I32 -> 1118.5
A33: 27 | B33: Stick to your Guns | C33: 3 | D33: 43672 | E33: =D33 -> 43672 | F33: 439 | G33: 700 | H33: =IFERROR(F33/G33,"") -> 0.62714286 | I33: =8226+AA33 -> 9392 | J33: =IFERROR(I33/F33,"") -> 21.394077 | K33: 4401 | L33: =IFERROR(K33/F33,"") -> 10.025057 | M33: 7000 | N33: =IFERROR(M33/I33,"") -> 0.74531516 | O33: =R33+U33 -> -873.63 | P33: =S33+V33 -> 4401 | Q33: =O33+P33 -> 3527.37 | R33: =(X33+AA33-AB33)*50% -> -436.815 | S33: =K33*50% -> 2200.5 | T33: =R33+S33 -> 1763.685 | U33: =R33 -> -436.815 | V33: =K33*50% -> 2200.5 | W33: =U33+V33 -> 1763.685 | X33: =-2039.63 -> -2039.63 | Y33: =T33+W33 -> 3527.37 | AA33: =881+285 -> 1166 | AD33: =R33+U33 -> -873.63
A34: 28 | B34: Zebbler Encanti Experience | C34: 8 | D34: 43673 | E34: =D34 -> 43673 | F34: 249 | G34: 700 | H34: =IFERROR(F34/G34,"") -> 0.35571429 | I34: 5006.25 | J34: =IFERROR(I34/F34,"") -> 20.105422 | K34: 2976 | L34: =IFERROR(K34/F34,"") -> 11.951807 | M34: 2900 | N34: =IFERROR(M34/I34,"") -> 0.57927591 | O34: =R34+U34 -> -359.2 | P34: =S34+V34 -> 2976 | Q34: =O34+P34 -> 2616.8 | R34: =(X34+AA34-AB34)*50% -> -179.6 | S34: =K34*50% -> 1488 | T34: =R34+S34 -> 1308.4 | U34: =R34 -> -179.6 | V34: =K34*50% -> 1488 | W34: =U34+V34 -> 1308.4 | X34: -359.2
A35: 29 | B35: Mr. Bill | C35: 8 | D35: 43680 | E35: =D35 -> 43680 | F35: 306 | G35: 700 | H35: =IFERROR(F35/G35,"") -> 0.43714286 | I35: 5794.25 | J35: =IFERROR(I35/F35,"") -> 18.935458 | K35: 4634 | L35: =IFERROR(K35/F35,"") -> 15.143791 | M35: 4400 | N35: =IFERROR(M35/I35,"") -> 0.75937352 | O35: =R35+U35 -> -1326.82 | P35: =S35+V35 -> 4634 | Q35: =O35+P35 -> 3307.18 | R35: =(X35+AA35-AB35)*50% -> -663.41 | S35: =K35*50% -> 2317 | T35: =R35+S35 -> 1653.59 | U35: =R35 -> -663.41 | V35: =K35*50% -> 2317 | W35: =U35+V35 -> 1653.59 | X35: -1326.82
A36: 30 | B36: Solardo | C36: 5 | D36: 43686 | E36: =D36 -> 43686 | F36: 373 | G36: 700 | H36: =IFERROR(F36/G36,"") -> 0.53285714 | I36: 7918.5 | J36: =IFERROR(I36/F36,"") -> 21.229223 | K36: 8868 | L36: =IFERROR(K36/F36,"") -> 23.774799 | M36: 5450 | N36: =IFERROR(M36/I36,"") -> 0.68826167 | O36: =R36+U36 -> -1515.91 | P36: =S36+V36 -> 8868 | Q36: =O36+P36 -> 7352.09 | R36: =(X36+AA36-AB36)*50% -> -757.955 | S36: =K36*50% -> 4434 | T36: =R36+S36 -> 3676.045 | U36: =R36 -> -757.955 | V36: =K36*50% -> 4434 | W36: =U36+V36 -> 3676.045 | X36: -1515.91
A37: 31 | B37: Why? | C37: 1 | D37: 43693 | E37: =D37 -> 43693 | F37: 156 | G37: 700 | H37: =IFERROR(F37/G37,"") -> 0.22285714 | I37: 3329.5 | J37: =IFERROR(I37/F37,"") -> 21.342949 | K37: 1971 | L37: =IFERROR(K37/F37,"") -> 12.634615 | M37: 4850 | N37: =IFERROR(M37/I37,"") -> 1.4566752 | O37: =R37+U37 -> -3924.69 | P37: =S37+V37 -> 1971 | Q37: =O37+P37 -> -1953.69 | R37: =(X37+AA37-AB37)*50% -> -1962.345 | S37: =K37*50% -> 985.5 | T37: =R37+S37 -> -976.845 | U37: =R37 -> -1962.345 | V37: =K37*50% -> 985.5 | W37: =U37+V37 -> -976.845 | X37: -3924.69
A38: 32 | B38: Polo G | C38: 2 | D38: 43705 | E38: =D38 -> 43705 | F38: 593 | G38: 800 | H38: =IFERROR(F38/G38,"") -> 0.74125 | I38: =19845+2537.75 -> 22382.75 | J38: =IFERROR(I38/F38,"") -> 37.744941 | K38: 1593 | L38: =IFERROR(K38/F38,"") -> 2.6863406 | M38: 11500 | N38: =IFERROR(M38/I38,"") -> 0.51378852 | O38: =R38+U38 -> 567.2 | P38: =S38+V38 -> 1593 | Q38: =O38+P38 -> 2160.2 | R38: =(X38+AA38-AB38)*50% -> 283.6 | S38: =K38*50% -> 796.5 | T38: =R38+S38 -> 1080.1 | U38: =R38 -> 283.6 | V38: =K38*50% -> 796.5 | W38: =U38+V38 -> 1080.1 | X38: -191.55 | Y38: =T38+W38 -> 2160.2 | AA38: =1562.75+510+465 -> 2537.75 | AB38: 1779
A39: 33 | B39: Jessica Hernandez & The Deltas | C39: 3 | D39: 43707 | E39: =D39 -> 43707 | F39: 261 | G39: 600 | H39: =IFERROR(F39/G39,"") -> 0.435 | I39: 4671 | J39: =IFERROR(I39/F39,"") -> 17.896552 | K39: 4031 | L39: =IFERROR(K39/F39,"") -> 15.444444 | M39: 5050 | N39: =IFERROR(M39/I39,"") -> 1.0811389 | O39: =R39+U39 -> -2665.01 | P39: =S39+V39 -> 4031 | Q39: =O39+P39 -> 1365.99 | R39: =(X39+AA39-AB39)*50% -> -1332.505 | S39: =K39*50% -> 2015.5 | T39: =R39+S39 -> 682.995 | U39: =R39 -> -1332.505 | V39: =K39*50% -> 2015.5 | W39: =U39+V39 -> 682.995 | X39: -2890.76 | AA39: =326.75+160 -> 486.75 | AB39: 261
A40: 34 | B40: Golden Features | C40: 2 | D40: 43713 | E40: =D40 -> 43713 | F40: 44 | G40: 700 | H40: =IFERROR(F40/G40,"") -> 0.062857143 | I40: =489+AA40 -> 587.5 | J40: =IFERROR(I40/F40,"") -> 13.352273 | K40: 580 | L40: =IFERROR(K40/F40,"") -> 13.181818 | M40: 1200 | N40: =IFERROR(M40/I40,"") -> 2.0425532 | O40: =R40+U40 -> -1911.52 | P40: =S40+V40 -> 580 | Q40: =O40+P40 -> -1331.52 | R40: =(X40+AA40-AB40)*50% -> -955.76 | S40: =K40*50% -> 290 | T40: =R40+S40 -> -665.76 | U40: =R40 -> -955.76 | V40: =K40*50% -> 290 | W40: =U40+V40 -> -665.76 | X40: -1878.02 | AA40: 98.5 | AB40: 132
A41: 35 | B41: BoomBox | C41: 2 | D41: 43715 | E41: =D41 -> 43715 | F41: 591 | G41: 850 | H41: =IFERROR(F41/G41,"") -> 0.69529412 | I41: =13280+AA41 -> 14479.5 | J41: =IFERROR(I41/F41,"") -> 24.5 | K41: 13713 | L41: =IFERROR(K41/F41,"") -> 23.203046 | M41: 10750 | N41: =IFERROR(M41/I41,"") -> 0.74242895 | O41: =R41+U41 -> -994.47 | P41: =S41+V41 -> 13713 | Q41: =O41+P41 -> 12718.53 | R41: =(X41+AA41-AB41)*50% -> -497.235 | S41: =K41*50% -> 6856.5 | T41: =R41+S41 -> 6359.265 | U41: =R41 -> -497.235 | V41: =K41*50% -> 6856.5 | W41: =U41+V41 -> 6359.265 | X41: -420.97 | AA41: 1199.5 | AB41: 1773
...

Sheet Magic Stick-by Promoter
B2: ***MAGIC STICK RESULTS*** | O2: MAGIC STICK TOTALS | S2: PROMOTER AVERAGES
B3: Name | D3: Shows | E3: Shows & Rentals | F3: Tickets Sold | G3: Venue Capacity | H3: Capacity Rate | I3: Gross Ticket Revenue | J3: Avg. Ticket Price (including TW rebate) | K3: Bar Revenue | L3: Avg sale of alcohol per guest | M3: Band(s) guarantee | N3: % of Gross Ticket Revenue | O3: Gate Settlement Gain/(Loss) | P3: Bar Sales - 100% | Q3: Show Gross Proceeds (before COGS, Labor, & Facility Costs) | R3: % of Total Gross Proceeds | S3: Gate Settlement Gain/(Loss) | T3: Bar Sales - 50% | U3: Show Gross Proceeds (before COGS, Labor, & Facility Costs)
B4: TOTALS | D4: =SUM(D7:D16) -> 60 | E4: =SUM(E7:E16) -> 61 | F4: =SUM(F7:F81) -> 28952 | G4: =SUM(G7:G81) -> 43700 | I4: =SUM(I7:I81) -> 754923 | K4: =SUM(K7:K81) -> 523492.54 | M4: =SUM(M7:M81) -> 456312.56 | N4: =SUM(N7:N81) -> 4.5034474 | O4: =SUM(O7:O81) -> 31502.43 | P4: =SUM(P7:P81) -> 523492.54 | Q4: =SUM(Q7:Q81) -> 554994.97 | R4: =SUM(R7:R81) -> 1
B5: AVERAGES | F5: =F4/D4 -> 482.53333 | G5: =G4/D4 -> 728.33333 | H5: =F4/G4 -> 0.66251716 | I5: =I4/D4 -> 12582.05 | J5: =I4/F4 -> 26.074986 | K5: =K4/E4 -> 8581.8449 | L5: =K4/F4 -> 18.081395 | M5: =M4/D4 -> 7605.2093 | N5: =M4/I4 -> 0.60444914 | O5: =O4/E4 -> 516.43328 | P5: =P4/E4 -> 8581.8449 | Q5: =Q4/E4 -> 9098.2782
A7: 5 | B7: Paxahau | D7: =COUNTIF('Magic Stick'!C:C,A:A) -> 17 | E7: =COUNTIF('Magic Stick'!C:C,A:A) -> 17 | F7: =SUMIF('Magic Stick'!$C:$C,A:A,'Magic Stick'!$F:$F) -> 11482 | G7: =SUMIF('Magic Stick'!$C:$C,A:A,'Magic Stick'!$G:$G) -> 12750 | H7: =F7/G7 -> 0.90054902 | I7: =SUMIF('Magic Stick'!$C:$C,A:A,'Magic Stick'!$I:$I) -> 328000.25 | J7: =I7/F7 -> 28.566474 | K7: =SUMIF('Magic Stick'!$C:$C,A:A,'Magic Stick'!$K:$K) -> 243601 | L7: =K7/F7 -> 21.215903 | M7: =SUMIF('Magic Stick'!$C:$C,A:A,'Magic Stick'!$M:$M) -> 189825 | N7: =M7/I7 -> 0.57873431 | O7: =SUMIF('Magic Stick'!$C:$C,A:A,'Magic Stick'!$O:$O) -> 46327.56 | P7: =K7 -> 243601 | Q7: =O7+P7 -> 289928.56 | R7: =Q7/$Q$4 -> 0.52239854 | S7: =O7/E7 -> 2725.1506 | T7: =P7/E7 -> 14329.471 | U7: =S7+T7 -> 17054.621
A8: 2 | B8: React co-pro | D8: =COUNTIF('Magic Stick'!C:C,A:A) -> 18 | E8: =COUNTIF('Magic Stick'!C:C,A:A) -> 18 | F8: =SUMIF('Magic Stick'!$C:$C,A:A,'Magic Stick'!$F:$F) -> 8732 | G8: =SUMIF('Magic Stick'!$C:$C,A:A,'Magic Stick'!$G:$G) -> 13300 | H8: =F8/G8 -> 0.65654135 | I8: =SUMIF('Magic Stick'!$C:$C,A:A,'Magic Stick'!$I:$I) -> 233329.5 | J8: =I8/F8 -> 26.721198 | K8: =SUMIF('Magic Stick'!$C:$C,A:A,'Magic Stick'!$K:$K) -> 158583.94 | L8: =K8/F8 -> 18.161239 | M8: =SUMIF('Magic Stick'!$C:$C,A:A,'Magic Stick'!$M:$M) -> 139778.79 | N8: =M8/I8 -> 0.5990618 | O8: =SUMIF('Magic Stick'!$C:$C,A:A,'Magic Stick'!$O:$O) -> -9362.13 | P8: =K8 -> 158583.94 | Q8: =O8+P8 -> 149221.81 | R8: =Q8/$Q$4 -> 0.26887056 | S8: =O8/E8 -> -520.11833 | T8: =P8/E8 -> 8810.2189 | U8: =S8+T8 -> 8290.1006
A9: 4 | B9: Good Show | D9: =COUNTIF('Magic Stick'!C:C,A:A) -> 4 | E9: =COUNTIF('Magic Stick'!C:C,A:A) -> 4 | F9: =SUMIF('Magic Stick'!$C:$C,A:A,'Magic Stick'!$F:$F) -> 2143 | G9: =SUMIF('Magic Stick'!$C:$C,A:A,'Magic Stick'!$G:$G) -> 2800 | H9: =F9/G9 -> 0.76535714 | I9: =SUMIF('Magic Stick'!$C:$C,A:A,'Magic Stick'!$I:$I) -> 56152.75 | J9: =I9/F9 -> 26.20287 | K9: =SUMIF('Magic Stick'!$C:$C,A:A,'Magic Stick'!$K:$K) -> 25534.7 | L9: =K9/F9 -> 11.915399 | M9: =SUMIF('Magic Stick'!$C:$C,A:A,'Magic Stick'!$M:$M) -> 32699.71 | N9: =M9/I9 -> 0.58233497 | O9: =SUMIF('Magic Stick'!$C:$C,A:A,'Magic Stick'!$O:$O) -> 5928.71 | P9: =K9 -> 25534.7 | Q9: =O9+P9 -> 31463.41 | R9: =Q9/$Q$4 -> 0.056691343 | S9: =O9/E9 -> 1482.1775 | T9: =P9/E9 -> 6383.675 | U9: =S9+T9 -> 7865.8525
A10: 8 | B10: Further Frequencies | D10: =COUNTIF('Magic Stick'!C:C,A:A) -> 8 | E10: =COUNTIF('Magic Stick'!C:C,A:A) -> 8 | F10: =SUMIF('Magic Stick'!$C:$C,A:A,'Magic Stick'!$F:$F) -> 2900 | G10: =SUMIF('Magic Stick'!$C:$C,A:A,'Magic Stick'!$G:$G) -> 5750 | H10: =F10/G10 -> 0.50434783 | I10: =SUMIF('Magic Stick'!$C:$C,A:A,'Magic Stick'!$I:$I) -> 56980.25 | J10: =I10/F10 -> 19.648362 | K10: =SUMIF('Magic Stick'!$C:$C,A:A,'Magic Stick'!$K:$K) -> 45576.5 | L10: =K10/F10 -> 15.716034 | M10: =SUMIF('Magic Stick'!$C:$C,A:A,'Magic Stick'!$M:$M) -> 30975 | N10: =M10/I10 -> 0.54360941 | O10: =SUMIF('Magic Stick'!$C:$C,A:A,'Magic Stick'!$O:$O) -> 7822.91 | P10: =K10 -> 45576.5 | Q10: =O10+P10 -> 53399.41 | R10: =Q10/$Q$4 -> 0.096216025 | S10: =O10/E10 -> 977.86375 | T10: =P10/E10 -> 5697.0625 | U10: =S10+T10 -> 6674.9263
A11: 7 | B11: Party Store co-pro | D11: =COUNTIF('Magic Stick'!C:C,A:A) -> 1 | E11: =COUNTIF('Magic Stick'!C:C,A:A) -> 1 | F11: =SUMIF('Magic Stick'!$C:$C,A:A,'Magic Stick'!$F:$F) -> 427 | G11: =SUMIF('Magic Stick'!$C:$C,A:A,'Magic Stick'!$G:$G) -> 700 | H11: =F11/G11 -> 0.61 | I11: =SUMIF('Magic Stick'!$C:$C,A:A,'Magic Stick'!$I:$I) -> 8988.5 | J11: =I11/F11 -> 21.050351 | K11: =SUMIF('Magic Stick'!$C:$C,A:A,'Magic Stick'!$K:$K) -> 2115.5 | L11: =K11/F11 -> 4.9543326 | M11: =SUMIF('Magic Stick'!$C:$C,A:A,'Magic Stick'!$M:$M) -> 5500 | N11: =M11/I11 -> 0.61189297 | O11: =SUMIF('Magic Stick'!$C:$C,A:A,'Magic Stick'!$O:$O) -> 450.29 | P11: =K11 -> 2115.5 | Q11: =O11+P11 -> 2565.79 | R11: =Q11/$Q$4 -> 0.0046230869 | S11: =O11/E11 -> 450.29 | T11: =P11/E11 -> 2115.5 | U11: =S11+T11 -> 2565.79
A12: 3 | B12: Black Iris | D12: =COUNTIF('Magic Stick'!C:C,A:A) -> 5 | E12: =COUNTIF('Magic Stick'!C:C,A:A) -> 5 | F12: =SUMIF('Magic Stick'!$C:$C,A:A,'Magic Stick'!$F:$F) -> 1400 | G12: =SUMIF('Magic Stick'!$C:$C,A:A,'Magic Stick'!$G:$G) -> 3500 | H12: =F12/G12 -> 0.4 | I12: =SUMIF('Magic Stick'!$C:$C,A:A,'Magic Stick'!$I:$I) -> 29836 | J12: =I12/F12 -> 21.311429 | K12: =SUMIF('Magic Stick'!$C:$C,A:A,'Magic Stick'!$K:$K) -> 19664.9 | L12: =K12/F12 -> 14.046357 | M12: =SUMIF('Magic Stick'!$C:$C,A:A,'Magic Stick'!$M:$M) -> 21684.06 | N12: =M12/I12 -> 0.72677504 | O12: =SUMIF('Magic Stick'!$C:$C,A:A,'Magic Stick'!$O:$O) -> -7805.36 | P12: =K12 -> 19664.9 | Q12: =O12+P12 -> 11859.54 | R12: =Q12/$Q$4 -> 0.021368734 | S12: =O12/E12 -> -1561.072 | T12: =P12/E12 -> 3932.98 | U12: =S12+T12 -> 2371.908
A13: 6 | B13: Rental event | E13: =COUNTIF('Magic Stick'!C:C,A:A) -> 1 | K13: =SUMIF('Magic Stick'!$C:$C,A:A,'Magic Stick'!$K:$K) -> 2361 | O13: =SUMIF('Magic Stick'!$C:$C,A:A,'Magic Stick'!$O:$O) -> -120 | P13: =K13 -> 2361 | Q13: =O13+P13 -> 2241 | R13: =Q13/$Q$4 -> 0.0040378744 | S13: =O13/E13 -> -120 | T13: =P13/E13 -> 2361 | U13: =S13+T13 -> 2241
A14: 1 | B14: Magic Stick in-house | D14: =COUNTIF('Magic Stick'!C:C,A:A) -> 7 | E14: =COUNTIF('Magic Stick'!C:C,A:A) -> 7 | F14: =SUMIF('Magic Stick'!$C:$C,A:A,'Magic Stick'!$F:$F) -> 1868 | G14: =SUMIF('Magic Stick'!$C:$C,A:A,'Magic Stick'!$G:$G) -> 4900 | H14: =F14/G14 -> 0.38122449 | I14: =SUMIF('Magic Stick'!$C:$C,A:A,'Magic Stick'!$I:$I) -> 41635.75 | J14: =I14/F14 -> 22.288945 | K14: =SUMIF('Magic Stick'!$C:$C,A:A,'Magic Stick'!$K:$K) -> 26055 | L14: =K14/F14 -> 13.948073 | M14: =SUMIF('Magic Stick'!$C:$C,A:A,'Magic Stick'!$M:$M) -> 35850 | N14: =M14/I14 -> 0.86103889 | O14: =SUMIF('Magic Stick'!$C:$C,A:A,'Magic Stick'!$O:$O) -> -11739.55 | P14: =K14 -> 26055 | Q14: =O14+P14 -> 14315.45 | R14: =Q14/$Q$4 -> 0.025793837 | S14: =O14/E14 -> -1677.0786 | T14: =P14/E14 -> 3722.1429 | U14: =S14+T14 -> 2045.0643
