Workbook

Sheet Magic Stick
O1: VENUE TOTAL
B2: ***MAGIC STICK RESULTS*** | O2: MAGIC STICK
B3: Name | C3: Promoter Code | D3: Date | E3: Day of the week | F3: Tickets Sold | G3: Venue Capacity | H3: Capacity Rate | I3: Gross Ticket Revenue | J3: Avg. Ticket Price (including TW rebate) | K3: Bar Revenue | L3: Avg sale of alcohol per guest | M3: Band(s) guarantee | N3: % of Gross Ticket Revenue | O3: Gate Settlement Gain/(Loss) | P3: Bar Sales - 100% | Q3: Show Gross Proceeds (before COGS, Labor, & Facility Costs)
B4: TOTALS | F4: =SUM(F7:F114) -> 33013 | G4: =SUM(G7:G114) -> 76457 | I4: =SUM(I7:I114) -> 1139644.4 | K4: =SUM(K7:K114) -> 699964.5 | M4: =SUM(M7:M114) -> 624775.14 | N4: =SUM(N7:N114) -> 64.223711 | O4: =SUM(O7:O114) -> 112015.24 | P4: =SUM(P7:P114) -> 699964.5 | Q4: =SUM(Q7:Q114) -> 811979.74
B5: AVERAGES | F5: =F4/COUNTA(F7:F114) -> 383.87209 | G5: =G4/COUNTA(G7:G114) -> 764.57 | H5: =F4/G4 -> 0.43178519 | I5: =I4/COUNTA(I7:I114) -> 13251.679 | J5: =I4/F4 -> 34.521079 | K5: =K4/COUNTA(K7:K114) -> 8139.1221 | L5: =K4/F4 -> 21.202693 | M5: =M4/COUNTA(M7:M114) -> 7264.8272 | N5: =M4/I4 -> 0.54821938 | O5: =O4/COUNTA(O7:O114) -> 1333.5148 | P5: =P4/COUNTA(P7:P114) -> 8139.1221 | Q5: =Q4/COUNTA(Q7:Q114) -> 8119.7974
A7: 1 | B7: Omnom | C7: 5 | D7: 45682 | E7: =D7 -> 45682 | F7: 819 | G7: 800 | H7: =IFERROR(F7/G7,"") -> 1.02375 | I7: 24929 | J7: =IFERROR(I7/F7,"") -> 30.438339 | K7: 20096 | L7: =IFERROR(K7/F7,"") -> 24.537241 | M7: =(5000+200+200+200) -> 5600 | N7: =IFERROR(M7/I7,"") -> 0.22463797 | O7: 8948.87 | P7: =K7 -> 20096 | Q7: =SUM(O7:P7) -> 29044.87
A8: 2 | B8: Fulton Lee | C8: 1 | D8: 45686 | E8: =D8 -> 45686 | F8: 307 | G8: 800 | H8: =IFERROR(F8/G8,"") -> 0.38375 | I8: 10997 | J8: =IFERROR(I8/F8,"") -> 35.820847 | K8: 2601 | L8: =IFERROR(K8/F8,"") -> 8.4723127 | M8: =5750 -> 5750 | N8: =IFERROR(M8/I8,"") -> 0.52286987 | O8: 1712.63 | P8: =K8 -> 2601 | Q8: =O8+P8 -> 4313.63
A9: 3 | B9: DJ Pauly D | C9: 5 | D9: 45688 | E9: =D9 -> 45688 | F9: 905 | G9: 781 | H9: =IFERROR(F9/G9,"") -> 1.1587708 | I9: 49813.5 | J9: =IFERROR(I9/F9,"") -> 55.042541 | K9: 31248 | L9: =IFERROR(K9/F9,"") -> 34.528177 | M9: =(30000+1026+200+250+250) -> 31726 | N9: =IFERROR(M9/I9,"") -> 0.63689562 | O9: 10101.91 | P9: =K9 -> 31248 | Q9: =O9+P9 -> 41349.91
A10: 4 | B10: Ayybo | C10: 5 | D10: 45689 | E10: =D10 -> 45689 | F10: 932 | G10: 750 | H10: =IFERROR(F10/G10,"") -> 1.2426667 | I10: 26036 | J10: =IFERROR(I10/F10,"") -> 27.935622 | K10: 26954 | L10: =IFERROR(K10/F10,"") -> 28.920601 | M10: =(3000+200+200) -> 3400 | N10: =IFERROR(M10/I10,"") -> 0.13058842 | O10: 10339.67 | P10: =K10 -> 26954 | Q10: =O10+P10 -> 37293.67
A11: 5 | B11: J Worra | C11: 5 | D11: 45695 | E11: =D11 -> 45695 | F11: 425 | G11: 800 | H11: =IFERROR(F11/G11,"") -> 0.53125 | I11: 11313.5 | J11: =IFERROR(I11/F11,"") -> 26.62 | K11: 11968 | L11: =IFERROR(K11/F11,"") -> 28.16 | M11: =(7500+200+200) -> 7900 | N11: =IFERROR(M11/I11,"") -> 0.69828082 | O11: -1581.03 | P11: =K11 -> 11968 | Q11: =O11+P11 -> 10386.97
A12: 6 | B12: Girl Math | C12: 5 | D12: 45702 | E12: =D12 -> 45702 | F12: 413 | G12: 800 | H12: =IFERROR(F12/G12,"") -> 0.51625 | I12: 9819.5 | J12: =IFERROR(I12/F12,"") -> 23.776029 | K12: 9578 | L12: =IFERROR(K12/F12,"") -> 23.191283 | M12: =(3000+3000+300) -> 6300 | N12: =IFERROR(M12/I12,"") -> 0.64158053 | O12: -1958.41 | P12: =K12 -> 9578 | Q12: =O12+P12 -> 7619.59
A13: 7 | B13: Boombox | C13: 1 | D13: 45703 | E13: =D13 -> 45703 | F13: 400 | G13: 800 | H13: =IFERROR(F13/G13,"") -> 0.5 | I13: 9951.75 | J13: =IFERROR(I13/F13,"") -> 24.879375 | K13: 7801 | L13: =IFERROR(K13/F13,"") -> 19.5025 | M13: =(6500+300) -> 6800 | N13: =IFERROR(M13/I13,"") -> 0.68329691 | O13: -375.11 | P13: =K13 -> 7801 | Q13: =O13+P13 -> 7425.89
A14: 8 | B14: Nemahsis | C14: 1 | D14: 45704 | E14: =D14 -> 45704 | F14: 402 | G14: 814 | H14: =IFERROR(F14/G14,"") -> 0.49385749 | I14: 14492 | J14: =IFERROR(I14/F14,"") -> 36.049751 | K14: 1556 | L14: =IFERROR(K14/F14,"") -> 3.8706468 | M14: =7500+500 -> 8000 | N14: =IFERROR(M14/I14,"") -> 0.55202871 | O14: 2796.84 | P14: =K14 -> 1556 | Q14: =O14+P14 -> 4352.84
A15: 9 | B15: Foster the People | C15: 5 | D15: 45705 | E15: =D15 -> 45705 | F15: 192 | G15: 800 | H15: =IFERROR(F15/G15,"") -> 0.24 | I15: 5536.5 | J15: =IFERROR(I15/F15,"") -> 28.835938 | K15: 3244 | L15: =IFERROR(K15/F15,"") -> 16.895833 | M15: =(2766+200) -> 2966 | N15: =IFERROR(M15/I15,"") -> 0.53571751 | O15: -457.02 | P15: =K15 -> 3244 | Q15: =O15+P15 -> 2786.98
A16: 10 | B16: Third Prty | C16: 2 | D16: 45709 | E16: =D16 -> 45709 | F16: 197 | G16: 800 | H16: =IFERROR(F16/G16,"") -> 0.24625 | I16: 5165.25 | J16: =IFERROR(I16/F16,"") -> 26.219543 | K16: 7279 | L16: =IFERROR(K16/F16,"") -> 36.949239 | M16: =(4000+350+200+150) -> 4700 | N16: =IFERROR(M16/I16,"") -> 0.90992692 | O16: -2227.39 | P16: =K16 -> 7279 | Q16: =O16+P16 -> 5051.61
A17: 11 | B17: JSTJR | C17: 2 | D17: 45710 | E17: =D17 -> 45710 | F17: 339 | G17: 800 | H17: =IFERROR(F17/G17,"") -> 0.42375 | I17: 10013.25 | J17: =IFERROR(I17/F17,"") -> 29.537611 | K17: 7400 | L17: =IFERROR(K17/F17,"") -> 21.828909 | M17: =(5000+300+250+150) -> 5700 | N17: =IFERROR(M17/I17,"") -> 0.56924575 | O17: 1129.18 | P17: =K17 -> 7400 | Q17: =O17+P17 -> 8529.18
A18: 12 | B18: LF System | C18: 2 | D18: 45717 | E18: =D18 -> 45717 | G18: 750 | H18: =IFERROR(F18/G18,"") -> 0 | J18: =IFERROR(I18/F18,"") | L18: =IFERROR(K18/F18,"") | N18: =IFERROR(M18/I18,"") | P18: =K18 | Q18: =O18+P18 -> 0
A19: 13 | B19: Paul van Dyk | C19: 5 | D19: 45730 | E19: =D19 -> 45730 | F19: 591 | G19: 800 | H19: =IFERROR(F19/G19,"") -> 0.73875 | I19: 17304 | J19: =IFERROR(I19/F19,"") -> 29.279188 | K19: 12779 | L19: =IFERROR(K19/F19,"") -> 21.622673 | M19: =10000 -> 10000 | N19: =IFERROR(M19/I19,"") -> 0.57790106 | O19: 1830.67 | P19: =K19 -> 12779 | Q19: =O19+P19 -> 14609.67
A20: 14 | B20: Dino Munaco | D20: 45731 | E20: =D20 -> 45731 | F20: 153 | G20: 750 | H20: =IFERROR(F20/G20,"") -> 0.204 | I20: 3470.5 | J20: =IFERROR(I20/F20,"") -> 22.683007 | K20: 4636 | L20: =IFERROR(K20/F20,"") -> 30.300654 | M20: =(500+700) -> 1200 | N20: =IFERROR(M20/I20,"") -> 0.3457715 | O20: 798.47 | P20: =K20 -> 4636 | Q20: =O20+P20 -> 5434.47
A21: 15 | B21: Qrion | C21: 5 | D21: 45737 | E21: =D21 -> 45737 | F21: 140 | G21: 800 | H21: =IFERROR(F21/G21,"") -> 0.175 | I21: 2678 | J21: =IFERROR(I21/F21,"") -> 19.128571 | K21: 2262 | L21: =IFERROR(K21/F21,"") -> 16.157143 | M21: =(2000+200+200) -> 2400 | N21: =IFERROR(M21/I21,"") -> 0.89619119 | O21: -2346.71 | P21: =K21 -> 2262 | Q21: =O21+P21 -> -84.71
A22: 16 | B22: Nora en Pure | C22: 5 | D22: 45744 | E22: =D22 -> 45744 | F22: 741 | G22: 750 | H22: =IFERROR(F22/G22,"") -> 0.988 | I22: 33729 | J22: =IFERROR(I22/F22,"") -> 45.518219 | K22: 18889 | L22: =IFERROR(K22/F22,"") -> 25.491228 | M22: =(25000+200+200) -> 25400 | N22: =IFERROR(M22/I22,"") -> 0.75306116 | O22: -513.1 | P22: =K22 -> 18889 | Q22: =O22+P22 -> 18375.9
A23: 17 | B23: Kaaze | C23: 2 | D23: 45369 | E23: =D23 -> 45369 | F23: 242 | G23: 750 | H23: =IFERROR(F23/G23,"") -> 0.32266667 | I23: 6432.25 | J23: =IFERROR(I23/F23,"") -> 26.579545 | K23: 5790 | L23: =IFERROR(K23/F23,"") -> 23.92562 | M23: =(5000+400+350) -> 5750 | N23: =IFERROR(M23/I23,"") -> 0.89393292 | O23: -2088.85 | P23: =K23 -> 5790 | Q23: =O23+P23 -> 3701.15
A24: 18 | B24: Marie Vaunt | C24: 2 | D24: 45751 | E24: =D24 -> 45751 | F24: 169 | G24: 1503 | H24: =IFERROR(F24/G24,"") -> 0.11244178 | I24: 4131.75 | J24: =IFERROR(I24/F24,"") -> 24.448225 | K24: 3327 | L24: =IFERROR(K24/F24,"") -> 19.686391 | M24: =(3500+300+200) -> 4000 | N24: =IFERROR(M24/I24,"") -> 0.96811279 | O24: -2789.39 | P24: =K24 -> 3327 | Q24: =O24+P24 -> 537.61
A25: 19 | B25: KC Lights | C25: 2 | D25: 45752 | E25: =D25 -> 45752 | F25: 271 | G25: 750 | H25: =IFERROR(F25/G25,"") -> 0.36133333 | I25: 6463 | J25: =IFERROR(I25/F25,"") -> 23.848708 | K25: 7878 | L25: =IFERROR(K25/F25,"") -> 29.070111 | M25: =(3500+1750+250+150) -> 5650 | N25: =IFERROR(M25/I25,"") -> 0.87420702 | O25: -2896.22 | P25: =K25 -> 7878 | Q25: =O25+P25 -> 4981.78
A26: 20 | B26: No Thanks | C26: 2 | D26: 45758 | E26: =D26 -> 45758 | F26: 170 | G26: 800 | H26: =IFERROR(F26/G26,"") -> 0.2125 | I26: 2327 | J26: =IFERROR(I26/F26,"") -> 13.688235 | K26: 3199 | L26: =IFERROR(K26/F26,"") -> 18.817647 | M26: =(3000+300+200) -> 3500 | N26: =IFERROR(M26/I26,"") -> 1.5040825 | O26: -3340.79 | P26: =K26 -> 3199 | Q26: =O26+P26 -> -141.79
A27: 21 | B27: Afrobeats to the World | C27: 1 | D27: 45759 | E27: =D27 -> 45759 | F27: 738 | G27: 800 | H27: =IFERROR(F27/G27,"") -> 0.9225 | I27: 21580 | J27: =IFERROR(I27/F27,"") -> 29.241192 | K27: 14283 | L27: =IFERROR(K27/F27,"") -> 19.353659 | M27: =16422 -> 16422 | N27: =IFERROR(M27/I27,"") -> 0.76098239 | O27: 2769.9 | P27: =K27 -> 14283 | Q27: =O27+P27 -> 17052.9
A28: 22 | B28: Ranger Trucco | C28: 5 | D28: 45766 | E28: =D28 -> 45766 | F28: 386 | G28: 750 | H28: =IFERROR(F28/G28,"") -> 0.51466667 | I28: 9980 | J28: =IFERROR(I28/F28,"") -> 25.854922 | K28: 9990 | L28: =IFERROR(K28/F28,"") -> 25.880829 | M28: 5000 | N28: =IFERROR(M28/I28,"") -> 0.501002 | O28: -49.74 | P28: =K28 -> 9990 | Q28: =O28+P28 -> 9940.26
A29: 23 | B29: Cristoph | C29: 5 | D29: 45772 | E29: =D29 -> 45772 | F29: 294 | G29: 750 | H29: =IFERROR(F29/G29,"") -> 0.392 | I29: 8409 | J29: =IFERROR(I29/F29,"") -> 28.602041 | K29: 7098 | L29: =IFERROR(K29/F29,"") -> 24.142857 | M29: 5000 | N29: =IFERROR(M29/I29,"") -> 0.59460102 | O29: -1382.41 | P29: =K29 -> 7098 | Q29: =O29+P29 -> 5715.59
A30: 24 | B30: Desert Hearts | C30: 5 | D30: 45773 | E30: =D30 -> 45773 | F30: 466 | G30: 750 | H30: =IFERROR(F30/G30,"") -> 0.62133333 | I30: 13895.75 | J30: =IFERROR(I30/F30,"") -> 29.819206 | K30: 12756 | L30: =IFERROR(K30/F30,"") -> 27.373391 | M30: =(2500+2500+2500) -> 7500 | N30: =IFERROR(M30/I30,"") -> 0.53973337 | O30: -2479.68 | P30: =K30 -> 12756 | Q30: =O30+P30 -> 10276.32
A31: 25 | B31: G-Space | C31: 5 | D31: 45780 | E31: =D31 -> 45780 | F31: 101 | G31: 754 | H31: =IFERROR(F31/G31,"") -> 0.13395225 | I31: 2492.5 | J31: =IFERROR(I31/F31,"") -> 24.678218 | K31: 2614 | L31: =IFERROR(K31/F31,"") -> 25.881188 | M31: =(3000+1000+500+150) -> 4650 | N31: =IFERROR(M31/I31,"") -> 1.8655968 | O31: 4030.77 | P31: =K31 -> 2614 | Q31: =O31+P31 -> 6644.77
A32: 26 | B32: Iann Dior | C32: 1 | D32: 45781 | E32: =D32 -> 45781 | F32: 228 | G32: 750 | H32: =IFERROR(F32/G32,"") -> 0.304 | I32: 11855.25 | J32: =IFERROR(I32/F32,"") -> 51.996711 | K32: 1736 | L32: =IFERROR(K32/F32,"") -> 7.6140351 | M32: =(6000+500) -> 6500 | N32: =IFERROR(M32/I32,"") -> 0.5482803 | O32: -2158.27 | P32: =K32 -> 1736 | Q32: =O32+P32 -> -422.27
A33: 27 | B33: Mereba | C33: 1 | D33: 45784 | E33: =D33 -> 45784 | F33: 314 | G33: 800 | H33: =IFERROR(F33/G33,"") -> 0.3925 | I33: 9547.5 | J33: =IFERROR(I33/F33,"") -> 30.406051 | K33: 2803 | L33: =IFERROR(K33/F33,"") -> 8.9267516 | M33: =3500+500 -> 4000 | N33: =IFERROR(M33/I33,"") -> 0.41895784 | O33: 2093.17 | P33: =K33 -> 2803 | Q33: =O33+P33 -> 4896.17
A34: 28 | B34: Klangkarussell | C34: 2 | D34: 45785 | E34: =D34 -> 45785 | F34: 196 | G34: 800 | H34: =IFERROR(F34/G34,"") -> 0.245 | I34: 5657 | J34: =IFERROR(I34/F34,"") -> 28.862245 | K34: 4391 | L34: =IFERROR(K34/F34,"") -> 22.403061 | M34: =(4000+150+300) -> 4450 | N34: =IFERROR(M34/I34,"") -> 0.78663603 | O34: -1741.99 | P34: =K34 -> 4391 | Q34: =O34+P34 -> 2649.01
A35: 29 | B35: Joe Kay | C35: 5 | D35: 45786 | E35: =D35 -> 45786 | F35: 741 | G35: 700 | H35: =IFERROR(F35/G35,"") -> 1.0585714 | I35: 31671 | J35: =IFERROR(I35/F35,"") -> 42.740891 | K35: 17147 | L35: =IFERROR(K35/F35,"") -> 23.140351 | M35: =(10000+500) -> 10500 | N35: =IFERROR(M35/I35,"") -> 0.33153358 | O35: 10300.4 | P35: =K35 -> 17147 | Q35: =O35+P35 -> 27447.4
A36: 30 | B36: Acraze | C36: 5 | D36: 45787 | E36: =D36 -> 45787 | F36: 500 | G36: 800 | H36: =IFERROR(F36/G36,"") -> 0.625 | I36: 16227 | J36: =IFERROR(I36/F36,"") -> 32.454 | K36: 12848 | L36: =IFERROR(K36/F36,"") -> 25.696 | M36: =(10000+200+200+200) -> 10600 | N36: =IFERROR(M36/I36,"") -> 0.65323227 | O36: 262.87 | P36: =K36 -> 12848 | Q36: =O36+P36 -> 13110.87
A37: 31 | B37: Raveena | C37: 1 | D37: 45788 | E37: =D37 -> 45788 | F37: 326 | G37: 750 | H37: =IFERROR(F37/G37,"") -> 0.43466667 | I37: 13887.75 | J37: =IFERROR(I37/F37,"") -> 42.60046 | K37: 1868.5 | L37: =IFERROR(K37/F37,"") -> 5.7315951 | M37: =(9000+500) -> 9500 | N37: =IFERROR(M37/I37,"") -> 0.68405609 | O37: -3025.89 | P37: =K37 -> 1868.5 | Q37: =O37+P37 -> -1157.39
A38: 32 | B38: A-Trak | C38: 5 | D38: 45419 | E38: =D38 -> 45419 | G38: 750 | H38: =IFERROR(F38/G38,"") -> 0 | J38: =IFERROR(I38/F38,"") | L38: =IFERROR(K38/F38,"") | N38: =IFERROR(M38/I38,"") | P38: =K38 | Q38: =O38+P38 -> 0
A39: 33 | B39: Baroness | C39: 1 | D39: 45794 | E39: =D39 -> 45794 | F39: 518 | G39: 750 | H39: =IFERROR(F39/G39,"") -> 0.69066667 | I39: 18635 | J39: =IFERROR(I39/F39,"") -> 35.974903 | K39: 7087 | L39: =IFERROR(K39/F39,"") -> 13.681467 | M39: =(8254.66+250) -> 8504.66 | N39: =IFERROR(M39/I39,"") -> 0.456381 | O39: 5443.21 | P39: =K39 -> 7087 | Q39: =O39+P39 -> 12530.21
A40: 34 | B40: Max Styler | C40: 5 | D40: 45800 | E40: =D40 -> 45800 | F40: 932 | G40: 800 | H40: =IFERROR(F40/G40,"") -> 1.165 | I40: 42057.5 | J40: =IFERROR(I40/F40,"") -> 45.126073 | K40: 31398 | L40: =IFERROR(K40/F40,"") -> 33.688841 | M40: =(12500+2200+400) -> 15100 | N40: =IFERROR(M40/I40,"") -> 0.35903228 | O40: 13560.94 | P40: =K40 -> 31398 | Q40: =O40+P40 -> 44958.94
A41: 35 | B41: Defected | C41: 5 | D41: 45801 | E41: =D41 -> 45801 | F41: 1005 | G41: 800 | H41: =IFERROR(F41/G41,"") -> 1.25625 | I41: 56166 | J41: =IFERROR(I41/F41,"") -> 55.886567 | K41: 21795 | L41: =IFERROR(K41/F41,"") -> 21.686567 | M41: =3500+10000 -> 13500 | N41: =IFERROR(M41/I41,"") -> 0.24035894 | O41: 25317.24 | P41: =K41 -> 21795 | Q41: =O41+P41 -> 47112.24
...

Sheet Magic Stick-by Promoter
B2: ***MAGIC STICK RESULTS*** | O2: MAGIC STICK TOTALS | S2: PROMOTER PER-SHOW AVERAGES
B3: Name | D3: Shows | E3: Shows & Rentals | F3: Tickets Sold | G3: Venue Capacity | H3: Capacity Rate | I3: Gross Ticket Revenue | J3: Avg. Ticket Price (including TW rebate) | K3: Bar Revenue | L3: Avg sale of alcohol per guest | M3: Band(s) guarantee | N3: % of Gross Ticket Revenue | O3: Gate Settlement Gain/(Loss) | P3: Bar Sales - 100% | Q3: Show Gross Proceeds (before COGS, Labor, & Facility Costs) | R3: % of Total Gross Proceeds | S3: Gate Settlement Gain/(Loss) | T3: Bar Sales - 50% | U3: Show Gross Proceeds (before COGS, Labor, & Facility Costs)
B4: TOTALS | D4: =SUM(D7:D16) -> 0 | E4: =SUM(E7:E16) -> 0 | F4: =SUM(F7:F81) -> 30956 | G4: =SUM(G7:G81) -> 62577 | I4: =SUM(I7:I81) -> 1079142.9 | K4: =SUM(K7:K81) -> 693608.5 | M4: =SUM(M7:M81) -> 594276.39 | N4: =SUM(N7:N81) -> #DIV/0! | O4: =SUM(O7:O81) -> 111503.69 | P4: =SUM(P7:P81) -> 693608.5 | Q4: =SUM(Q7:Q81) -> 805112.19 | R4: =SUM(R7:R81) -> 1
B5: AVERAGES | F5: =F4/D4 -> #DIV/0! | G5: =G4/D4 -> #DIV/0! | H5: =F4/G4 -> 0.49468655 | I5: =I4/D4 -> #DIV/0! | J5: =I4/F4 -> 34.860542 | K5: =K4/E4 -> #DIV/0! | L5: =K4/F4 -> 22.40627 | M5: =M4/D4 -> #DIV/0! | N5: =M4/I4 -> 0.55069293 | O5: =O4/E4 -> #DIV/0! | P5: =P4/E4 -> #DIV/0! | Q5: =Q4/E4 -> #DIV/0!
A7: 5 | B7: Paxahau - Tom Pattyn | D7: {=COUNTIF('Magic Stick'!C:C,A:A)} -> 0 | E7: {=COUNTIF('Magic Stick'!C:C,A:A)} -> 0 | F7: =SUMIF('Magic Stick'!$C:$C,A:A,'Magic Stick'!$F:$F) -> 17464 | G7: =SUMIF('Magic Stick'!$C:$C,A:A,'Magic Stick'!$G:$G) -> 28685 | H7: =F7/G7 -> 0.60881994 | I7: =SUMIF('Magic Stick'!$C:$C,A:A,'Magic Stick'!$I:$I) -> 639925.49 | J7: =I7/F7 -> 36.64255 | K7: =SUMIF('Magic Stick'!$C:$C,A:A,'Magic Stick'!$K:$K) -> 446372 | L7: =K7/F7 -> 25.559551 | M7: =SUMIF('Magic Stick'!$C:$C,A:A,'Magic Stick'!$M:$M) -> 322205.52 | N7: =M7/I7 -> 0.50350474 | O7: =SUMIF('Magic Stick'!$C:$C,A:A,'Magic Stick'!$O:$O) -> 94869.37 | P7: =K7 -> 446372 | Q7: =O7+P7 -> 541241.37 | R7: =Q7/$Q$4 -> 0.67225584 | S7: =O7/E7 -> #DIV/0! | T7: =P7/E7 -> #DIV/0! | U7: =S7+T7 -> #DIV/0!
A8: 1 | B8: In-House - Zach | D8: {=COUNTIF('Magic Stick'!C:C,A:A)} -> 0 | E8: {=COUNTIF('Magic Stick'!C:C,A:A)} -> 0 | F8: =SUMIF('Magic Stick'!$C:$C,A:A,'Magic Stick'!$F:$F) -> 10711 | G8: =SUMIF('Magic Stick'!$C:$C,A:A,'Magic Stick'!$G:$G) -> 22039 | H8: =F8/G8 -> 0.48600209 | I8: =SUMIF('Magic Stick'!$C:$C,A:A,'Magic Stick'!$I:$I) -> 365844.38 | J8: =I8/F8 -> 34.15595 | K8: =SUMIF('Magic Stick'!$C:$C,A:A,'Magic Stick'!$K:$K) -> 142168.5 | L8: =K8/F8 -> 13.27313 | M8: =SUMIF('Magic Stick'!$C:$C,A:A,'Magic Stick'!$M:$M) -> 208620.87 | N8: =M8/I8 -> 0.57024484 | O8: =SUMIF('Magic Stick'!$C:$C,A:A,'Magic Stick'!$O:$O) -> 32587.81 | P8: =K8 -> 142168.5 | Q8: =O8+P8 -> 174756.31 | R8: =Q8/$Q$4 -> 0.21705833 | S8: =O8/E8 -> #DIV/0! | T8: =P8/E8 -> #DIV/0! | U8: =S8+T8 -> #DIV/0!
A9: 2 | B9: In-House - Brie | D9: {=COUNTIF('Magic Stick'!C:C,A:A)} -> 0 | E9: {=COUNTIF('Magic Stick'!C:C,A:A)} -> 0 | F9: =SUMIF('Magic Stick'!$C:$C,A:A,'Magic Stick'!$F:$F) -> 2781 | G9: =SUMIF('Magic Stick'!$C:$C,A:A,'Magic Stick'!$G:$G) -> 11853 | H9: =F9/G9 -> 0.23462415 | I9: =SUMIF('Magic Stick'!$C:$C,A:A,'Magic Stick'!$I:$I) -> 73373.08 | J9: =I9/F9 -> 26.383704 | K9: =SUMIF('Magic Stick'!$C:$C,A:A,'Magic Stick'!$K:$K) -> 63821 | L9: =K9/F9 -> 22.948939 | M9: =SUMIF('Magic Stick'!$C:$C,A:A,'Magic Stick'!$M:$M) -> 63450 | N9: =M9/I9 -> 0.86475857 | O9: =SUMIF('Magic Stick'!$C:$C,A:A,'Magic Stick'!$O:$O) -> -29837.12 | P9: =K9 -> 63821 | Q9: =O9+P9 -> 33983.88 | R9: =Q9/$Q$4 -> 0.042210117 | S9: =O9/E9 -> #DIV/0! | T9: =P9/E9 -> #DIV/0! | U9: =S9+T9 -> #DIV/0!
A10: 8 | B10: Further Frequencies | D10: {=COUNTIF('Magic Stick'!C:C,A:A)} -> 0 | E10: {=COUNTIF('Magic Stick'!C:C,A:A)} -> 0 | F10: =SUMIF('Magic Stick'!$C:$C,A:A,'Magic Stick'!$F:$F) -> 0 | G10: =SUMIF('Magic Stick'!$C:$C,A:A,'Magic Stick'!$G:$G) -> 0 | H10: =F10/G10 -> #DIV/0! | I10: =SUMIF('Magic Stick'!$C:$C,A:A,'Magic Stick'!$I:$I) -> 0 | J10: =I10/F10 -> #DIV/0! | K10: =SUMIF('Magic Stick'!$C:$C,A:A,'Magic Stick'!$K:$K) -> 0 | L10: =K10/F10 -> #DIV/0! | M10: =SUMIF('Magic Stick'!$C:$C,A:A,'Magic Stick'!$M:$M) -> 0 | N10: =M10/I10 -> #DIV/0! | O10: =SUMIF('Magic Stick'!$C:$C,A:A,'Magic Stick'!$O:$O) -> 0 | P10: =K10 -> 0 | Q10: =O10+P10 -> 0 | R10: =Q10/$Q$4 -> 0 | S10: =O10/E10 -> #DIV/0! | T10: =P10/E10 -> #DIV/0! | U10: =S10+T10 -> #DIV/0!
A11: 4 | B11: Good Show - Jason Berry | D11: {=COUNTIF('Magic Stick'!C:C,A:A)} -> 0 | E11: {=COUNTIF('Magic Stick'!C:C,A:A)} -> 0 | F11: =SUMIF('Magic Stick'!$C:$C,A:A,'Magic Stick'!$F:$F) -> 0 | G11: =SUMIF('Magic Stick'!$C:$C,A:A,'Magic Stick'!$G:$G) -> 0 | H11: =F11/G11 -> #DIV/0! | I11: =SUMIF('Magic Stick'!$C:$C,A:A,'Magic Stick'!$I:$I) -> 0 | J11: =I11/F11 -> #DIV/0! | K11: =SUMIF('Magic Stick'!$C:$C,A:A,'Magic Stick'!$K:$K) -> 0 | L11: =K11/F11 -> #DIV/0! | M11: =SUMIF('Magic Stick'!$C:$C,A:A,'Magic Stick'!$M:$M) -> 0 | N11: =M11/I11 -> #DIV/0! | O11: =SUMIF('Magic Stick'!$C:$C,A:A,'Magic Stick'!$O:$O) -> 0 | P11: =K11 -> 0 | Q11: =O11+P11 -> 0 | R11: =Q11/$Q$4 -> 0 | S11: =O11/E11 -> #DIV/0! | T11: =P11/E11 -> #DIV/0! | U11: =S11+T11 -> #DIV/0!
A12: 3 | B12: Black Iris | D12: {=COUNTIF('Magic Stick'!C:C,A:A)} -> 0 | E12: {=COUNTIF('Magic Stick'!C:C,A:A)} -> 0 | F12: =SUMIF('Magic Stick'!$C:$C,A:A,'Magic Stick'!$F:$F) -> 0 | G12: =SUMIF('Magic Stick'!$C:$C,A:A,'Magic Stick'!$G:$G) -> 0 | H12: =F12/G12 -> #DIV/0! | I12: =SUMIF('Magic Stick'!$C:$C,A:A,'Magic Stick'!$I:$I) -> 0 | J12: =I12/F12 -> #DIV/0! | K12: =SUMIF('Magic Stick'!$C:$C,A:A,'Magic Stick'!$K:$K) -> 0 | L12: =K12/F12 -> #DIV/0! | M12: =SUMIF('Magic Stick'!$C:$C,A:A,'Magic Stick'!$M:$M) -> 0 | N12: =M12/I12 -> #DIV/0! | O12: =SUMIF('Magic Stick'!$C:$C,A:A,'Magic Stick'!$O:$O) -> 0 | P12: =K12 -> 0 | Q12: =O12+P12 -> 0 | R12: =Q12/$Q$4 -> 0 | S12: =O12/E12 -> #DIV/0! | T12: =P12/E12 -> #DIV/0! | U12: =S12+T12 -> #DIV/0!
A13: 6 | B13: Rental event | E13: {=COUNTIF('Magic Stick'!C:C,A:A)} -> 0 | K13: =SUMIF('Magic Stick'!$C:$C,A:A,'Magic Stick'!$K:$K) -> 41247 | O13: =SUMIF('Magic Stick'!$C:$C,A:A,'Magic Stick'!$O:$O) -> 13883.63 | P13: =K13 -> 41247 | Q13: =O13+P13 -> 55130.63 | R13: =Q13/$Q$4 -> 0.068475711 | S13: =O13/E13 -> #DIV/0! | T13: =P13/E13 -> #DIV/0! | U13: =S13+T13 -> #DIV/0!
A14: 7 | B14: Party Store co-pro | D14: {=COUNTIF('Magic Stick'!C:C,A:A)} -> 0 | E14: {=COUNTIF('Magic Stick'!C:C,A:A)} -> 0 | F14: =SUMIF('Magic Stick'!$C:$C,A:A,'Magic Stick'!$F:$F) -> 0 | G14: =SUMIF('Magic Stick'!$C:$C,A:A,'Magic Stick'!$G:$G) -> 0 | H14: =F14/G14 -> #DIV/0! | I14: =SUMIF('Magic Stick'!$C:$C,A:A,'Magic Stick'!$I:$I) -> 0 | J14: =I14/F14 -> #DIV/0! | K14: =SUMIF('Magic Stick'!$C:$C,A:A,'Magic Stick'!$K:$K) -> 0 | L14: =K14/F14 -> #DIV/0! | M14: =SUMIF('Magic Stick'!$C:$C,A:A,'Magic Stick'!$M:$M) -> 0 | N14: =M14/I14 -> #DIV/0! | O14: =SUMIF('Magic Stick'!$C:$C,A:A,'Magic Stick'!$O:$O) -> 0 | P14: =K14 -> 0 | Q14: =O14+P14 -> 0 | R14: =Q14/$Q$4 -> 0 | S14: =O14/E14 -> #DIV/0! | T14: =P14/E14 -> #DIV/0! | U14: =S14+T14 -> #DIV/0!
